<?xml version="1.0"?>
<!-- ===================================================================================
   --><!-- |    This document was autogenerated by xacro from
/home/user/projects/shadow_robot/base/src/sr_common/sr_description/robots/sr_hand.urdf.xacro
   | --><!-- |    EDITING THIS FILE BY HAND IS NOT RECOMMENDED                
                   | --><!--
===================================================================================
   --><!-- Software License Agreement (BSD License) Copyright xA9 2022 belongs
   to Shadow Robot Company Ltd. All rights reserved. Redistribution and use in
   source and binary forms, with or without modification, are permitted provided
   that the following conditions are met:   1. Redistributions of source code must
   retain the above copyright notice,      this list of conditions and the following
   disclaimer.   2. Redistributions in binary form must reproduce the above copyright
   notice,      this list of conditions and the following disclaimer in the documentation
        and/or other materials provided with the distribution.   3. Neither the
   name of Shadow Robot Company Ltd nor the names of its contributors      may
   be used to endorse or promote products derived from this software without  
      specific prior written permission. This software is provided by Shadow Robot
   Company Ltd "as is" and any express or implied warranties, including, but
   not limited to, the implied warranties of merchantability and fitness for a
   particular purpose are disclaimed. In no event shall the copyright holder be
   liable for any direct, indirect, incidental, special, exemplary, or consequential
   damages (including, but not limited to, procurement of substitute goods or services;
   loss of use, data, or profits; or business interruption) however caused and
   on any theory of liability, whether in contract, strict liability, or tort (including
   negligence or otherwise) arising in any way out of the use of this software,
   even if advised of the possibility of such damage.-->
<robot name="shadowhand_motor"
  xmlns:controller="http://playerstage.sourceforge.net/gazebo/xmlschema/#controller"
  xmlns:interface="http://playerstage.sourceforge.net/gazebo/xmlschema/#interface"
  xmlns:sensor="http://playerstage.sourceforge.net/gazebo/xmlschema/#sensor">
  <material name="Blue">
    <color rgba="0.0 0.0 0.8 1.0" />
  </material>
  <material name="Green">
    <color rgba="0.0 0.8 0.0 1.0" />
  </material>
  <material name="BiotacGreen">
    <color rgba="0.31 0.85 0.42 1.0" />
  </material>
  <material name="Grey">
    <color rgba="0.2 0.2 0.2 1.0" />
  </material>
  <material name="LightGrey">
    <color rgba="0.6 0.6 0.6 1.0"
    />
  </material>
  <material name="Red">
    <color rgba="0.8 0.0 0.0 1.0"
    />
  </material>
  <material name="White">
    <color rgba="1.0 1.0 1.0 1.0"
    />
  </material>
  <gazebo>
    <plugin filename="libgazebo_ros_control.so"
      name="gazebo_ros_control">
      <robotSimType>sr_gazebo_sim/SrGazeboHWSim</robotSimType>
    </plugin>
  </gazebo>
  <link name="world" />
  <joint name="rh_world_joint"
    type="fixed">
    <parent link="world" />
    <child link="rh_forearm"
    />
    <origin rpy="0.0 0.0 0.0" xyz="0.0 0.0 0.0" />
  </joint>
  <link name="
  rh_forearm">
    <inertial>
      <origin rpy="0 0 0" xyz="0 0 0.09" />
      <mass value="3.0" />
      <inertia ixx="0.0138" ixy="0.0" ixz="0.0"
        iyy="0.0138" iyz="0.0" izz="0.00744" />
    </inertial>
    <visual>
      <origin rpy="0 0 0" xyz="0 0 0.0" />
      <geometry name="rh_forearm_visual"
      >
        <mesh filename="package://sr_description/meshes/components/forearm/forearm_E3M5.dae"
          scale="0.001 0.001 0.001" />
      </geometry>
      <material name="light_grey"
      >
        <color rgba="0.90000 0.90000 0.90000 1.0" />
      </material>
    </visual>
    <collision>
      <origin rpy="0 0 0" xyz="0 0 0.0" />
      <geometry name="rh_forearm_collision">
        <mesh
          filename="package://sr_description/meshes/components/forearm/forearm_collision_E3M5.dae"
          scale="0.001 0.001 0.001" />
      </geometry>
    </collision>    <!-- wrist
   mount -->
    <collision>
      <origin rpy="0 0.78 0" xyz="0 -0.01 0.181"
      />
      <geometry>
        <box size="0.07 0.07 0.07" />
      </geometry>
    </collision>    <!-- TODO: Make a decision on
    whether to add the connector
   or not -->    <!--visual>
    <origin rpy="0 -1.57 -1.57" xyz="0.0 0.067
   0.0045"/>        <geometry name="${prefix}cable_extr_visualisation">  
          <mesh
    filename="package://sr_description/meshes/components/cable_connector/cable_connector_base_${hand_version}.dae"
   scale="0.001 0.001 0.001" />        </geometry>      </visual-->
  </link>
  <gazebo reference="rh_forearm">
    <selfCollide>false</selfCollide>
  </gazebo>
  <link name="rh_wrist">
    <inertial>
      <origin rpy="0 0 0" xyz="
  0 0 0.029" />
      <mass value="0.1" />
      <inertia ixx="0.000035" ixy="
  0.0" ixz="0.0" iyy="0.000064" iyz="0.0" izz="0.0000438" />
    </inertial>
    <visual>
      <origin rpy="0 0 0" xyz="0 0 0" />
      <geometry name="
  rh_wrist_visual">
        <mesh filename="package://sr_description/meshes/components/wrist/wrist_E3M5.dae"
          scale="0.001 0.001 0.001" />
      </geometry>
      <material name="LightGrey"
      />
    </visual>
    <collision>
      <origin rpy="1.5708 1.5708 0" xyz="
  0 0 0" />
      <geometry name="rh_wrist_collision_geom">
        <cylinder
          length="0.030" radius="0.0135" />
      </geometry>
    </collision>
    <collision>
      <origin rpy="0 1.5708 0" xyz="-0.026 0 0.034" />
      <geometry>
        <cylinder length="0.010" radius="0.011" />
      </geometry>
    </collision>
    <collision>
      <origin rpy="0 1.5708 0" xyz="0.031
   0 0.034" />
      <geometry>
        <cylinder length="0.010" radius="0.011"
        />
      </geometry>
    </collision>
    <collision>
      <origin rpy="0
   0.7854 0" xyz="-0.021 0 0.011" />
      <geometry>
        <box size="0.027
   0.018 0.010" />
      </geometry>
    </collision>
    <collision>
      <origin
        rpy="0 -0.7854 0" xyz="0.026 0 0.010" />
      <geometry>
        <box size="
  0.027 0.018 0.010" />
      </geometry>
    </collision>
  </link>
  <gazebo
    reference="rh_wrist">
    <material>Gazebo/White</material>
    <selfCollide>false</selfCollide>
  </gazebo>
  <joint name="rh_WRJ2" type="revolute">
    <parent link="
  rh_forearm" />
    <child link="rh_wrist" />
    <origin rpy="0 0 0" xyz="
  0 -0.010 0.21301" />
    <axis xyz="0 1 0" />
    <limit effort="10" lower="
  -0.5235987755982988" upper="0.17453292519943295" velocity="2.0" />
    <dynamics
      damping="0.1" />
  </joint>
  <gazebo reference="rh_WRJ2">
    <provideFeedback>1</provideFeedback>
    <implicitSpringDamper>1</implicitSpringDamper>
  </gazebo>
  <transmission
    name="rh_wrist_transmission">
    <type>sr_mechanism_model/SimpleTransmission</type>
    <actuator name="rh_WRJ2">
      <mechanicalReduction>1</mechanicalReduction>
    </actuator>
    <joint name="rh_WRJ2">
      <hardwareInterface>EffortJointInterface</hardwareInterface>
      <hardwareInterface>PositionJointInterface</hardwareInterface>
    </joint>
  </transmission>
  <link name="rh_palm">
    <inertial>
      <origin rpy="
  0 0 0" xyz="0 0 0.035" />
      <mass value="0.3" />
      <inertia ixx="
  0.0003581" ixy="0.0" ixz="0.0" iyy="0.0005287" iyz="0.0" izz="0.000191"
      />
    </inertial>
    <visual>
      <origin rpy="0 0 0" xyz="0 0 0" />
      <geometry name="rh_palm_visual">
        <mesh filename="package://sr_description/meshes/components/palm/palm_E3M5.dae"
          scale="0.001 0.001 0.001" />
      </geometry>
      <material name="Grey"
      />
    </visual>
    <collision>
      <origin rpy="0 0 0" xyz="0.011 0.0085
   0.038" />
      <geometry name="rh_palm_collision_geom">
        <box size="
  0.062 0.007 0.098" />
      </geometry>
    </collision>
    <collision>
      <origin rpy="0 0 0" xyz="-0.002 -0.0035 0.038" />
      <geometry>
        <box size="0.036 0.017 0.098" />
      </geometry>
    </collision>
    <!-- palm complement below first finger -->
    <collision>
      <origin
        rpy="0 0 0" xyz="0.029 -0.0035 0.082" />
      <geometry>
        <box size="
  0.026 0.017 0.010" />
      </geometry>
    </collision>
    <collision>
      <origin rpy="0.2 0 0.25" xyz="0.0265 -0.001 0.070" />
      <geometry>
        <box size="0.026 0.014 0.018" />
      </geometry>
    </collision>
    <!-- thumb pulp side -->
    <collision>
      <origin rpy="0 0 0" xyz="
  0.0315 -0.0085 0.001" />
      <geometry>
        <box size="0.021 0.027 0.024"
        />
      </geometry>
    </collision>    <!-- thumb pulp central -->
    <collision>
      <origin rpy="0 0 -0.48" xyz="0.0125 -0.015 0.009" />
      <geometry>
        <box size="0.022 0.005 0.040" />
      </geometry>
    </collision>
    <!-- above middle finger-->
    <collision>
      <origin rpy="0 0 0" xyz="
  0.011 0 0.089" />
      <geometry>
        <box size="0.018 0.024 0.004" />
      </geometry>
    </collision>    <!-- metacarpal side-->
    <collision>
      <origin rpy="0 0 0" xyz="-0.03 0 0.009" />
      <geometry>
        <box size="0.020 0.024 0.040" />
      </geometry>
    </collision>
  </link>
  <joint name="rh_ee_fixed_joint" type="fixed">
    <parent link="rh_palm"
    />
    <child link="rh_manipulator" />
    <origin rpy="0.0 0.0 0.0" xyz="
  0.0 0.0 0.05" />
  </joint>
  <link name="rh_manipulator" />
  <joint name="
  rh_WRJ1" type="revolute">
    <parent link="rh_wrist" />
    <child link="
  rh_palm" />
    <origin rpy="0 0 0" xyz="0 0 0.034" />
    <axis xyz="1 0
   0" />
    <limit effort="30" lower="-0.6981317007977318" upper="0.4886921905584123"
      velocity="2.0" />
    <dynamics damping="0.1" />
  </joint>
  <gazebo reference="
  rh_WRJ1">
    <provideFeedback>1</provideFeedback>
    <implicitSpringDamper>1</implicitSpringDamper>
  </gazebo>
  <link name="rh_imu" />
  <joint name="rh_palm_to_imu" type="
  fixed">
    <parent link="rh_palm" />
    <child link="rh_imu" />
    <origin
      rpy="-1.5707963 3.141592 0.0" xyz="0.01785 0.00765 0.049125" />
  </joint>
  <transmission name="rh_palm_transmission">
    <type>sr_mechanism_model/SimpleTransmission</type>
    <actuator name="rh_WRJ1">
      <mechanicalReduction>1</mechanicalReduction>
    </actuator>
    <joint name="rh_WRJ1">
      <hardwareInterface>EffortJointInterface</hardwareInterface>
      <hardwareInterface>PositionJointInterface</hardwareInterface>
    </joint>
  </transmission>
  <gazebo reference="rh_palm"> </gazebo>
  <link name="
  rh_ffknuckle">
    <inertial>
      <origin rpy="0 0 0" xyz="0 0 0" />
      <mass value="0.008" />
      <inertia ixx="0.00000026" ixy="0.0" ixz="
  0.0" iyy="0.00000026" iyz="0.0" izz="0.00000032" />
    </inertial>
    <visual>
      <origin rpy="0 0 0" xyz="0 0 0.0005" />
      <geometry name="
  rh_ffknuckle_visual">
        <mesh filename="package://sr_description/meshes/components/f_knuckle/f_knuckle_E3M5.dae"
          scale="0.001 0.001 0.001" />
      </geometry>
      <material name="LightGrey"
      />
    </visual>
    <collision>
      <origin rpy="0 1.5708 0" xyz="0 0 0"
      />
      <geometry name="rh_ffknuckle_collision_geom">
        <cylinder length="
  0.014" radius="0.007" />
      </geometry>
    </collision>
  </link>
  <joint
    name="rh_FFJ4" type="revolute">
    <parent link="rh_palm" />
    <child
      link="rh_ffknuckle" />    <!--<origin
    xyz="0.033 0 0.095" rpy="0 0 0" />-->
    <origin rpy="0 0 0" xyz="0.033 0 0.095" />
    <axis xyz="0 -1 0" />
    <limit effort="2" lower="-0.3490658503988659" upper="0.3490658503988659"
      velocity="2.0" />
    <dynamics damping="0.1" />
  </joint>
  <gazebo reference="
  rh_FFJ4">
    <provideFeedback>1</provideFeedback>
    <implicitSpringDamper>1</implicitSpringDamper>
  </gazebo>
  <transmission name="rh_ffknuckle_transmission">
    <type>sr_mechanism_model/SimpleTransmission</type>
    <actuator name="rh_FFJ4">
      <mechanicalReduction>1</mechanicalReduction>
    </actuator>
    <joint name="rh_FFJ4">
      <hardwareInterface>EffortJointInterface</hardwareInterface>
      <hardwareInterface>PositionJointInterface</hardwareInterface>
    </joint>
  </transmission>
  <gazebo reference="rh_ffknuckle">    <!-- knuckle is not
   highly exposed, so bumper is not useful -->
    <material>Gazebo/Grey</material>
  </gazebo>
  <link name="rh_ffproximal">
    <inertial>
      <mass value="
  0.030" />
      <origin xyz="0 0 0.0225" />
      <inertia ixx="0.0000098"
        ixy="0.0" ixz="0.0" iyy="0.00001" iyz="0.0" izz="0.0000018" />
    </inertial>
    <visual>
      <origin rpy="0 0 0" xyz="0 0 0" />
      <geometry name="
  rh_ffproximal_visual">
        <mesh filename="package://sr_description/meshes/components/f_proximal/f_proximal_E3M5.dae"
          scale="0.001 0.001 0.001" />
      </geometry>
      <material name="Grey"
      />
    </visual>
    <collision>
      <origin rpy="0 0 0" xyz="0 0 0.025"
      />
      <geometry name="rh_ffproximal_collision_geom">
        <cylinder length="
  0.040" radius="0.007" />
      </geometry>
    </collision>
  </link>
  <joint
    name="rh_FFJ3" type="revolute">
    <parent link="rh_ffknuckle" />
    <child link="rh_ffproximal" />
    <origin rpy="0 0 0" xyz="0 0 0" />
    <axis xyz="1 0 0" />
    <limit effort="2" lower="-0.2617993877991494"
      upper="1.5707963267948966" velocity="2.0" />
    <dynamics damping="0.1"
    />
  </joint>
  <gazebo reference="rh_FFJ3">
    <provideFeedback>1</provideFeedback>
    <implicitSpringDamper>1</implicitSpringDamper>
  </gazebo>
  <transmission
    name="rh_ffproximal_transmission">
    <type>sr_mechanism_model/SimpleTransmission</type>
    <actuator name="rh_FFJ3">
      <mechanicalReduction>1</mechanicalReduction>
    </actuator>
    <joint name="rh_FFJ3">
      <hardwareInterface>EffortJointInterface</hardwareInterface>
      <hardwareInterface>PositionJointInterface</hardwareInterface>
    </joint>
  </transmission>
  <gazebo reference="rh_ffproximal">
    <selfCollide>true</selfCollide>
  </gazebo>
  <link name="rh_ffmiddle">
    <inertial>
      <origin rpy="
  0 0 0" xyz="0 0 0.0125" />
      <mass value="0.017" />
      <inertia ixx="
  0.0000026" ixy="0.0" ixz="0.0" iyy="0.0000027" iyz="0.0" izz="0.00000087"
      />
    </inertial>
    <visual>
      <origin rpy="0 0 0" xyz="0 0 0" />
      <geometry name="rh_ffmiddle_visual">
        <mesh filename="package://sr_description/meshes/components/f_middle/f_middle_E3M5.dae"
          scale="0.001 0.001 0.001" />
      </geometry>
      <material name="Grey"
      />
    </visual>
    <collision>
      <origin rpy="0 0 0" xyz="0 0 0.0125"
      />
      <geometry name="rh_ffmiddle_collision_geom">
        <cylinder length="
  0.025" radius="0.007" />
      </geometry>
    </collision>
    <collision>
      <origin rpy="0 0 0" xyz="0 0 0.0" />
      <geometry>
        <sphere
          radius="0.007" />
      </geometry>
    </collision>
    <collision>
      <origin rpy="0 0 0" xyz="0 0 0.025" />
      <geometry>
        <sphere
          radius="0.007" />
      </geometry>
    </collision>
  </link>
  <joint name="
  rh_FFJ2" type="revolute">
    <parent link="rh_ffproximal" />
    <child link="
  rh_ffmiddle" />
    <origin rpy="0 0 0" xyz="0 0 0.045" />
    <axis xyz="
  1 0 0" />
    <limit effort="2" lower="0" upper="1.5707963267948966" velocity="
  2.0" />
    <dynamics damping="0.1" />
  </joint>
  <gazebo reference="rh_FFJ2"
  >
    <provideFeedback>1</provideFeedback>
    <implicitSpringDamper>1</implicitSpringDamper>
  </gazebo>
  <transmission name="rh_ffmiddle_transmission">
    <type>sr_mechanism_model/J0Transmission</type>
    <actuator name="rh_FFJ0">
      <mechanicalReduction>1</mechanicalReduction>
    </actuator>
    <joint name="rh_FFJ1">
      <hardwareInterface>EffortJointInterface</hardwareInterface>
      <hardwareInterface>PositionJointInterface</hardwareInterface>
    </joint>
  </transmission>
  <gazebo reference="rh_ffmiddle">
    <selfCollide>true</selfCollide>
  </gazebo>
  <link name="rh_ffdistal">
    <inertial>
      <mass value="
  0.012" />
      <origin xyz="0 0 0.012" />
      <inertia ixx="0.00000094"
        ixy="0.0" ixz="0.0" iyy="0.0000011" iyz="0.0" izz="0.00000053" />
    </inertial>
    <visual>
      <origin rpy="0 0 0" xyz="0 0 0" />
      <geometry name="rh_ffdistal_visual">
        <mesh filename="package://sr_description/meshes/components/f_distal/mst/f_distal_mstXL.dae"
          scale="0.001 0.001 0.001" />
      </geometry>
    </visual>
    <collision>
      <origin rpy="0 0 0" xyz="0 0 0" />
      <geometry name="rh_ffdistal_collision_geom"
      >
        <mesh filename="package://sr_description/meshes/components/f_distal/mst/f_distal_mstXL.dae"
          scale="0.001 0.001 0.001" />
      </geometry>
    </collision>
  </link>
  <joint name="rh_FFJ1" type="revolute">
    <parent link="rh_ffmiddle"
    />
    <child link="rh_ffdistal" />
    <origin rpy="0 0 0" xyz="0 0 0.025"
    />
    <axis xyz="1 0 0" />    <!-- standard distal joint -->
    <limit effort="
  2" lower="0" upper="1.5707963267948966" velocity="2.0" />
    <dynamics damping="
  0.1" />
  </joint>
  <gazebo reference="rh_FFJ1">
    <provideFeedback>1</provideFeedback>
    <implicitSpringDamper>1</implicitSpringDamper>
  </gazebo>
  <link name="
  rh_fftip">
    <inertial>
      <mass value="0.001" />
      <inertia ixx="
  0.0" ixy="0.0" ixz="0.0" iyy="0.0" iyz="0.0" izz="0.0" />
    </inertial>
  </link>
  <joint name="rh_FFtip" type="fixed">
    <parent link="rh_ffdistal"
    />
    <child link="rh_fftip" />
    <origin rpy="0 0 0" xyz="0 0 0.026"
    />
  </joint>
  <link name="rh_ff_mst_link" />
  <joint name="rh_ffdistal_to_mst_joint"
    type="fixed">
    <parent link="rh_ffdistal" />
    <child link="rh_ff_mst_link"
    />
    <origin rpy="0 0 0" xyz="0.0 0.0 0.0" />
  </joint>  <!-- Note that
   all the following transforms were obtained using the script `get_taxel_tfs_from_meshes,py`
          Using the material available in the folders `meshes/f_distal_XL` and
  `meshes/mstXL_distal_isolated_magnets
   -->
  <link name="rh_ff_taxel_0" />
  <joint name="rh_ff_mst_to_taxel_0"
    type="fixed">
    <parent link="rh_ff_mst_link" />
    <child link="rh_ff_taxel_0"
    />
    <origin rpy="-1.51978666 1.44937453e-04 1.45968674"
      xyz="-0.00921687001
   0.00099373239 0.02038228873" />
  </joint>
  <link name="rh_ff_taxel_1" />
  <joint name="rh_ff_mst_to_taxel_1" type="fixed">
    <parent link="rh_ff_mst_link"
    />
    <child link="rh_ff_taxel_1" />
    <origin rpy="-1.59559695 -3.48829319e-04
   2.41934577"
      xyz="-0.00640312645 -0.0065173749 0.018270370759999998" />
  </joint>
  <link name="rh_ff_taxel_2" />
  <joint name="rh_ff_mst_to_taxel_2" type="
  fixed">
    <parent link="rh_ff_mst_link" />
    <child link="rh_ff_taxel_2"
    />
    <origin rpy="-1.65955903 -0.00541627 2.51722701"
      xyz="-0.0066597394100000006
   -0.00576875338 0.01260740369" />
  </joint>
  <link name="rh_ff_taxel_3" />
  <joint name="rh_ff_mst_to_taxel_3" type="fixed">
    <parent link="rh_ff_mst_link"
    />
    <child link="rh_ff_taxel_3" />
    <origin rpy="-1.54268087 6.45535715e-05
   1.40876949"
      xyz="-0.00942467165 0.00123111485 0.013959520520000001" />
  </joint>
  <link name="rh_ff_taxel_4" />
  <joint name="rh_ff_mst_to_taxel_4" type="
  fixed">
    <parent link="rh_ff_mst_link" />
    <child link="rh_ff_taxel_4"
    />
    <origin rpy="-1.29061943 0.00168711 1.52628765"
      xyz="-0.00867928261 0.00090325075
   0.02632664124" />
  </joint>
  <link name="rh_ff_taxel_5" />
  <joint name="
  rh_ff_mst_to_taxel_5" type="fixed">
    <parent link="rh_ff_mst_link" />
    <child link="rh_ff_taxel_5" />
    <origin rpy="-1.19846222 0.08480638 -2.49594701"
      xyz="0.00569565306 -0.00539249259 0.0253778316" />
  </joint>
  <link name="
  rh_ff_taxel_6" />
  <joint name="rh_ff_mst_to_taxel_6" type="fixed">
    <parent
      link="rh_ff_mst_link" />
    <child link="rh_ff_taxel_6" />
    <origin rpy="
  -1.29057253 -0.00189879 -1.52072868"
      xyz="0.00871833126 0.00099431703 0.0261743809"
    />
  </joint>
  <link name="rh_ff_taxel_7" />
  <joint name="rh_ff_mst_to_taxel_7"
    type="fixed">
    <parent link="rh_ff_mst_link" />
    <child link="rh_ff_taxel_7"
    />
    <origin rpy="-1.60361784 5.95662030e-04 -2.40698274"
      xyz="0.00664900914
   -0.00630558868 0.018515388730000002" />
  </joint>
  <link name="rh_ff_taxel_8"
  />
  <joint name="rh_ff_mst_to_taxel_8" type="fixed">
    <parent link="
  rh_ff_mst_link" />
    <child link="rh_ff_taxel_8" />
    <origin rpy="-1.65580869
   1.83052213e-03 -3.13786483"
      xyz="0.00014411317000000002 -0.008049275 0.014931109360000002"
    />
  </joint>
  <link name="rh_ff_taxel_9" />
  <joint name="rh_ff_mst_to_taxel_9"
    type="fixed">
    <parent link="rh_ff_mst_link" />
    <child link="rh_ff_taxel_9"
    />
    <origin rpy="-1.19878812 -0.08458215 2.49544358"
      xyz="-0.0057381420800000004
   -0.0054270967900000005 0.02524200553" />
  </joint>
  <link name="rh_ff_taxel_10"
  />
  <joint name="rh_ff_mst_to_taxel_10" type="fixed">
    <parent link="
  rh_ff_mst_link" />
    <child link="rh_ff_taxel_10" />
    <origin rpy="-1.54285408
   -5.71837391e-05 -1.42527418"
      xyz="0.00942258829 0.00115158208 0.01454831045"
    />
  </joint>
  <link name="rh_ff_taxel_11" />
  <joint name="rh_ff_mst_to_taxel_11"
    type="fixed">
    <parent link="rh_ff_mst_link" />
    <child link="rh_ff_taxel_11"
    />
    <origin rpy="-0.46989731  0.10702183 -1.78833246"
      xyz="0.0038067269 -0.00023025534
   0.03188900555" />
  </joint>
  <link name="rh_ff_taxel_12" />
  <joint name="
  rh_ff_mst_to_taxel_12" type="fixed">
    <parent link="rh_ff_mst_link" />
    <child link="rh_ff_taxel_12" />
    <origin rpy="-0.90945336 -0.00352009
   -3.1076869"
      xyz="2.6127978100000003e-05  -0.00484799149 0.0292631876" />
  </joint>
  <link name="rh_ff_taxel_13" />
  <joint name="rh_ff_mst_to_taxel_13"
    type="fixed">
    <parent link="rh_ff_mst_link" />
    <child link="rh_ff_taxel_13"
    />
    <origin rpy="0.40261749 0.27093248 -1.7070713"
      xyz="-0.00392243091 -5.411787e-05
   0.03187189268" />
  </joint>
  <link name="rh_ff_taxel_14" />
  <joint name="
  rh_ff_mst_to_taxel_14" type="fixed">
    <parent link="rh_ff_mst_link" />
    <child link="rh_ff_taxel_14" />
    <origin rpy="-1.653756 0.00455583 -2.49848336"
      xyz="0.00672575877 -0.0056872052 0.01228742454" />
  </joint>
  <link name="
  rh_ff_taxel_15" />
  <joint name="rh_ff_mst_to_taxel_15" type="fixed">
    <parent link="rh_ff_mst_link" />
    <child link="rh_ff_taxel_15" />
    <origin rpy="-1.52010616 -1.02741516e-04 -1.49088185"
      xyz="0.00919364576 0.00107233058
   0.02073499409" />
  </joint>
  <link name="rh_ff_taxel_16" />
  <joint name="
  rh_ff_mst_to_taxel_16" type="fixed">
    <parent link="rh_ff_mst_link" />
    <child link="rh_ff_taxel_16" />
    <origin rpy="-1.38286616 0.00525309
   -3.12116599"
      xyz="0.00016191958000000002 -0.008007749670000001 0.02215694734"
    />
  </joint>
  <gazebo reference="rh_ffdistal">
    <sensor name="rh_ffdistal_contact"
      type="contact">
      <always_on>1</always_on>
      <update_rate>1000.0</update_rate>
      <contact>
        <collision>rh_ffdistal_collision</collision>
        <topic>rh_ffdistal_collision</topic>
      </contact>
      <plugin filename="
  libgazebo_ros_bumper.so" name="rh_ffdistal_gazebo_ros_bumper_controller">
        <alwaysOn>true</alwaysOn>
        <frameName>rh_ffdistal</frameName>
        <updateRate>100.0</updateRate>
        <bumperTopicName>contacts/rh_ff/distal</bumperTopicName>
      </plugin>
    </sensor>
    <mu1 value="500.0" />
    <mu2 value="500.0"
    />
    <kp value="10000000.0" />
    <kd value="1.0" />
    <selfCollide>true</selfCollide>
  </gazebo>
  <link name="rh_mfknuckle">
    <inertial>
      <origin rpy="
  0 0 0" xyz="0 0 0" />
      <mass value="0.008" />
      <inertia ixx="0.00000026"
        ixy="0.0" ixz="0.0" iyy="0.00000026" iyz="0.0" izz="0.00000032" />
    </inertial>
    <visual>
      <origin rpy="0 0 0" xyz="0 0 0.0005" />
      <geometry name="rh_mfknuckle_visual">
        <mesh filename="package://sr_description/meshes/components/f_knuckle/f_knuckle_E3M5.dae"
          scale="0.001 0.001 0.001" />
      </geometry>
      <material name="LightGrey"
      />
    </visual>
    <collision>
      <origin rpy="0 1.5708 0" xyz="0 0 0"
      />
      <geometry name="rh_mfknuckle_collision_geom">
        <cylinder length="
  0.014" radius="0.007" />
      </geometry>
    </collision>
  </link>
  <joint
    name="rh_MFJ4" type="revolute">
    <parent link="rh_palm" />
    <child
      link="rh_mfknuckle" />    <!--<origin
    xyz="0.033 0 0.095" rpy="0 0 0" />-->
    <origin rpy="0 0 0" xyz="0.011 0 0.099" />
    <axis xyz="0 -1 0" />
    <limit effort="2" lower="-0.3490658503988659" upper="0.3490658503988659"
      velocity="2.0" />
    <dynamics damping="0.1" />
  </joint>
  <gazebo reference="
  rh_MFJ4">
    <provideFeedback>1</provideFeedback>
    <implicitSpringDamper>1</implicitSpringDamper>
  </gazebo>
  <transmission name="rh_mfknuckle_transmission">
    <type>sr_mechanism_model/SimpleTransmission</type>
    <actuator name="rh_MFJ4">
      <mechanicalReduction>1</mechanicalReduction>
    </actuator>
    <joint name="rh_MFJ4">
      <hardwareInterface>EffortJointInterface</hardwareInterface>
      <hardwareInterface>PositionJointInterface</hardwareInterface>
    </joint>
  </transmission>
  <gazebo reference="rh_mfknuckle">    <!-- knuckle is not
   highly exposed, so bumper is not useful -->
    <material>Gazebo/Grey</material>
  </gazebo>
  <link name="rh_mfproximal">
    <inertial>
      <mass value="
  0.030" />
      <origin xyz="0 0 0.0225" />
      <inertia ixx="0.0000098"
        ixy="0.0" ixz="0.0" iyy="0.00001" iyz="0.0" izz="0.0000018" />
    </inertial>
    <visual>
      <origin rpy="0 0 0" xyz="0 0 0" />
      <geometry name="
  rh_mfproximal_visual">
        <mesh filename="package://sr_description/meshes/components/f_proximal/f_proximal_E3M5.dae"
          scale="0.001 0.001 0.001" />
      </geometry>
      <material name="Grey"
      />
    </visual>
    <collision>
      <origin rpy="0 0 0" xyz="0 0 0.025"
      />
      <geometry name="rh_mfproximal_collision_geom">
        <cylinder length="
  0.040" radius="0.007" />
      </geometry>
    </collision>
  </link>
  <joint
    name="rh_MFJ3" type="revolute">
    <parent link="rh_mfknuckle" />
    <child link="rh_mfproximal" />
    <origin rpy="0 0 0" xyz="0 0 0" />
    <axis xyz="1 0 0" />
    <limit effort="2" lower="-0.2617993877991494"
      upper="1.5707963267948966" velocity="2.0" />
    <dynamics damping="0.1"
    />
  </joint>
  <gazebo reference="rh_MFJ3">
    <provideFeedback>1</provideFeedback>
    <implicitSpringDamper>1</implicitSpringDamper>
  </gazebo>
  <transmission
    name="rh_mfproximal_transmission">
    <type>sr_mechanism_model/SimpleTransmission</type>
    <actuator name="rh_MFJ3">
      <mechanicalReduction>1</mechanicalReduction>
    </actuator>
    <joint name="rh_MFJ3">
      <hardwareInterface>EffortJointInterface</hardwareInterface>
      <hardwareInterface>PositionJointInterface</hardwareInterface>
    </joint>
  </transmission>
  <gazebo reference="rh_mfproximal">
    <selfCollide>true</selfCollide>
  </gazebo>
  <link name="rh_mfmiddle">
    <inertial>
      <origin rpy="
  0 0 0" xyz="0 0 0.0125" />
      <mass value="0.017" />
      <inertia ixx="
  0.0000026" ixy="0.0" ixz="0.0" iyy="0.0000027" iyz="0.0" izz="0.00000087"
      />
    </inertial>
    <visual>
      <origin rpy="0 0 0" xyz="0 0 0" />
      <geometry name="rh_mfmiddle_visual">
        <mesh filename="package://sr_description/meshes/components/f_middle/f_middle_E3M5.dae"
          scale="0.001 0.001 0.001" />
      </geometry>
      <material name="Grey"
      />
    </visual>
    <collision>
      <origin rpy="0 0 0" xyz="0 0 0.0125"
      />
      <geometry name="rh_mfmiddle_collision_geom">
        <cylinder length="
  0.025" radius="0.007" />
      </geometry>
    </collision>
    <collision>
      <origin rpy="0 0 0" xyz="0 0 0.0" />
      <geometry>
        <sphere
          radius="0.007" />
      </geometry>
    </collision>
    <collision>
      <origin rpy="0 0 0" xyz="0 0 0.025" />
      <geometry>
        <sphere
          radius="0.007" />
      </geometry>
    </collision>
  </link>
  <joint name="
  rh_MFJ2" type="revolute">
    <parent link="rh_mfproximal" />
    <child link="
  rh_mfmiddle" />
    <origin rpy="0 0 0" xyz="0 0 0.045" />
    <axis xyz="
  1 0 0" />
    <limit effort="2" lower="0" upper="1.5707963267948966" velocity="
  2.0" />
    <dynamics damping="0.1" />
  </joint>
  <gazebo reference="rh_MFJ2"
  >
    <provideFeedback>1</provideFeedback>
    <implicitSpringDamper>1</implicitSpringDamper>
  </gazebo>
  <transmission name="rh_mfmiddle_transmission">
    <type>sr_mechanism_model/J0Transmission</type>
    <actuator name="rh_MFJ0">
      <mechanicalReduction>1</mechanicalReduction>
    </actuator>
    <joint name="rh_MFJ1">
      <hardwareInterface>EffortJointInterface</hardwareInterface>
      <hardwareInterface>PositionJointInterface</hardwareInterface>
    </joint>
  </transmission>
  <gazebo reference="rh_mfmiddle">
    <selfCollide>true</selfCollide>
  </gazebo>
  <link name="rh_mfdistal">
    <inertial>
      <mass value="
  0.012" />
      <origin xyz="0 0 0.012" />
      <inertia ixx="0.00000094"
        ixy="0.0" ixz="0.0" iyy="0.0000011" iyz="0.0" izz="0.00000053" />
    </inertial>
    <visual>
      <origin rpy="0 0 0" xyz="0 0 0" />
      <geometry name="rh_mfdistal_visual">
        <mesh filename="package://sr_description/meshes/components/f_distal/mst/f_distal_mstXL.dae"
          scale="0.001 0.001 0.001" />
      </geometry>
    </visual>
    <collision>
      <origin rpy="0 0 0" xyz="0 0 0" />
      <geometry name="rh_mfdistal_collision_geom"
      >
        <mesh filename="package://sr_description/meshes/components/f_distal/mst/f_distal_mstXL.dae"
          scale="0.001 0.001 0.001" />
      </geometry>
    </collision>
  </link>
  <joint name="rh_MFJ1" type="revolute">
    <parent link="rh_mfmiddle"
    />
    <child link="rh_mfdistal" />
    <origin rpy="0 0 0" xyz="0 0 0.025"
    />
    <axis xyz="1 0 0" />    <!-- standard distal joint -->
    <limit effort="
  2" lower="0" upper="1.5707963267948966" velocity="2.0" />
    <dynamics damping="
  0.1" />
  </joint>
  <gazebo reference="rh_MFJ1">
    <provideFeedback>1</provideFeedback>
    <implicitSpringDamper>1</implicitSpringDamper>
  </gazebo>
  <link name="
  rh_mftip">
    <inertial>
      <mass value="0.001" />
      <inertia ixx="
  0.0" ixy="0.0" ixz="0.0" iyy="0.0" iyz="0.0" izz="0.0" />
    </inertial>
  </link>
  <joint name="rh_MFtip" type="fixed">
    <parent link="rh_mfdistal"
    />
    <child link="rh_mftip" />
    <origin rpy="0 0 0" xyz="0 0 0.026"
    />
  </joint>
  <link name="rh_mf_mst_link" />
  <joint name="rh_mfdistal_to_mst_joint"
    type="fixed">
    <parent link="rh_mfdistal" />
    <child link="rh_mf_mst_link"
    />
    <origin rpy="0 0 0" xyz="0.0 0.0 0.0" />
  </joint>  <!-- Note that
   all the following transforms were obtained using the script `get_taxel_tfs_from_meshes,py`
          Using the material available in the folders `meshes/f_distal_XL` and
  `meshes/mstXL_distal_isolated_magnets
   -->
  <link name="rh_mf_taxel_0" />
  <joint name="rh_mf_mst_to_taxel_0"
    type="fixed">
    <parent link="rh_mf_mst_link" />
    <child link="rh_mf_taxel_0"
    />
    <origin rpy="-1.51978666 1.44937453e-04 1.45968674"
      xyz="-0.00921687001
   0.00099373239 0.02038228873" />
  </joint>
  <link name="rh_mf_taxel_1" />
  <joint name="rh_mf_mst_to_taxel_1" type="fixed">
    <parent link="rh_mf_mst_link"
    />
    <child link="rh_mf_taxel_1" />
    <origin rpy="-1.59559695 -3.48829319e-04
   2.41934577"
      xyz="-0.00640312645 -0.0065173749 0.018270370759999998" />
  </joint>
  <link name="rh_mf_taxel_2" />
  <joint name="rh_mf_mst_to_taxel_2" type="
  fixed">
    <parent link="rh_mf_mst_link" />
    <child link="rh_mf_taxel_2"
    />
    <origin rpy="-1.65955903 -0.00541627 2.51722701"
      xyz="-0.0066597394100000006
   -0.00576875338 0.01260740369" />
  </joint>
  <link name="rh_mf_taxel_3" />
  <joint name="rh_mf_mst_to_taxel_3" type="fixed">
    <parent link="rh_mf_mst_link"
    />
    <child link="rh_mf_taxel_3" />
    <origin rpy="-1.54268087 6.45535715e-05
   1.40876949"
      xyz="-0.00942467165 0.00123111485 0.013959520520000001" />
  </joint>
  <link name="rh_mf_taxel_4" />
  <joint name="rh_mf_mst_to_taxel_4" type="
  fixed">
    <parent link="rh_mf_mst_link" />
    <child link="rh_mf_taxel_4"
    />
    <origin rpy="-1.29061943 0.00168711 1.52628765"
      xyz="-0.00867928261 0.00090325075
   0.02632664124" />
  </joint>
  <link name="rh_mf_taxel_5" />
  <joint name="
  rh_mf_mst_to_taxel_5" type="fixed">
    <parent link="rh_mf_mst_link" />
    <child link="rh_mf_taxel_5" />
    <origin rpy="-1.19846222 0.08480638 -2.49594701"
      xyz="0.00569565306 -0.00539249259 0.0253778316" />
  </joint>
  <link name="
  rh_mf_taxel_6" />
  <joint name="rh_mf_mst_to_taxel_6" type="fixed">
    <parent
      link="rh_mf_mst_link" />
    <child link="rh_mf_taxel_6" />
    <origin rpy="
  -1.29057253 -0.00189879 -1.52072868"
      xyz="0.00871833126 0.00099431703 0.0261743809"
    />
  </joint>
  <link name="rh_mf_taxel_7" />
  <joint name="rh_mf_mst_to_taxel_7"
    type="fixed">
    <parent link="rh_mf_mst_link" />
    <child link="rh_mf_taxel_7"
    />
    <origin rpy="-1.60361784 5.95662030e-04 -2.40698274"
      xyz="0.00664900914
   -0.00630558868 0.018515388730000002" />
  </joint>
  <link name="rh_mf_taxel_8"
  />
  <joint name="rh_mf_mst_to_taxel_8" type="fixed">
    <parent link="
  rh_mf_mst_link" />
    <child link="rh_mf_taxel_8" />
    <origin rpy="-1.65580869
   1.83052213e-03 -3.13786483"
      xyz="0.00014411317000000002 -0.008049275 0.014931109360000002"
    />
  </joint>
  <link name="rh_mf_taxel_9" />
  <joint name="rh_mf_mst_to_taxel_9"
    type="fixed">
    <parent link="rh_mf_mst_link" />
    <child link="rh_mf_taxel_9"
    />
    <origin rpy="-1.19878812 -0.08458215 2.49544358"
      xyz="-0.0057381420800000004
   -0.0054270967900000005 0.02524200553" />
  </joint>
  <link name="rh_mf_taxel_10"
  />
  <joint name="rh_mf_mst_to_taxel_10" type="fixed">
    <parent link="
  rh_mf_mst_link" />
    <child link="rh_mf_taxel_10" />
    <origin rpy="-1.54285408
   -5.71837391e-05 -1.42527418"
      xyz="0.00942258829 0.00115158208 0.01454831045"
    />
  </joint>
  <link name="rh_mf_taxel_11" />
  <joint name="rh_mf_mst_to_taxel_11"
    type="fixed">
    <parent link="rh_mf_mst_link" />
    <child link="rh_mf_taxel_11"
    />
    <origin rpy="-0.46989731  0.10702183 -1.78833246"
      xyz="0.0038067269 -0.00023025534
   0.03188900555" />
  </joint>
  <link name="rh_mf_taxel_12" />
  <joint name="
  rh_mf_mst_to_taxel_12" type="fixed">
    <parent link="rh_mf_mst_link" />
    <child link="rh_mf_taxel_12" />
    <origin rpy="-0.90945336 -0.00352009
   -3.1076869"
      xyz="2.6127978100000003e-05  -0.00484799149 0.0292631876" />
  </joint>
  <link name="rh_mf_taxel_13" />
  <joint name="rh_mf_mst_to_taxel_13"
    type="fixed">
    <parent link="rh_mf_mst_link" />
    <child link="rh_mf_taxel_13"
    />
    <origin rpy="0.40261749 0.27093248 -1.7070713"
      xyz="-0.00392243091 -5.411787e-05
   0.03187189268" />
  </joint>
  <link name="rh_mf_taxel_14" />
  <joint name="
  rh_mf_mst_to_taxel_14" type="fixed">
    <parent link="rh_mf_mst_link" />
    <child link="rh_mf_taxel_14" />
    <origin rpy="-1.653756 0.00455583 -2.49848336"
      xyz="0.00672575877 -0.0056872052 0.01228742454" />
  </joint>
  <link name="
  rh_mf_taxel_15" />
  <joint name="rh_mf_mst_to_taxel_15" type="fixed">
    <parent link="rh_mf_mst_link" />
    <child link="rh_mf_taxel_15" />
    <origin rpy="-1.52010616 -1.02741516e-04 -1.49088185"
      xyz="0.00919364576 0.00107233058
   0.02073499409" />
  </joint>
  <link name="rh_mf_taxel_16" />
  <joint name="
  rh_mf_mst_to_taxel_16" type="fixed">
    <parent link="rh_mf_mst_link" />
    <child link="rh_mf_taxel_16" />
    <origin rpy="-1.38286616 0.00525309
   -3.12116599"
      xyz="0.00016191958000000002 -0.008007749670000001 0.02215694734"
    />
  </joint>
  <gazebo reference="rh_mfdistal">
    <sensor name="rh_mfdistal_contact"
      type="contact">
      <always_on>1</always_on>
      <update_rate>1000.0</update_rate>
      <contact>
        <collision>rh_mfdistal_collision</collision>
        <topic>rh_mfdistal_collision</topic>
      </contact>
      <plugin filename="
  libgazebo_ros_bumper.so" name="rh_mfdistal_gazebo_ros_bumper_controller">
        <alwaysOn>true</alwaysOn>
        <frameName>rh_mfdistal</frameName>
        <updateRate>100.0</updateRate>
        <bumperTopicName>contacts/rh_mf/distal</bumperTopicName>
      </plugin>
    </sensor>
    <mu1 value="500.0" />
    <mu2 value="500.0"
    />
    <kp value="10000000.0" />
    <kd value="1.0" />
    <selfCollide>true</selfCollide>
  </gazebo>
  <link name="rh_rfknuckle">
    <inertial>
      <origin rpy="
  0 0 0" xyz="0 0 0" />
      <mass value="0.008" />
      <inertia ixx="0.00000026"
        ixy="0.0" ixz="0.0" iyy="0.00000026" iyz="0.0" izz="0.00000032" />
    </inertial>
    <visual>
      <origin rpy="0 0 0" xyz="0 0 0.0005" />
      <geometry name="rh_rfknuckle_visual">
        <mesh filename="package://sr_description/meshes/components/f_knuckle/f_knuckle_E3M5.dae"
          scale="0.001 0.001 0.001" />
      </geometry>
      <material name="LightGrey"
      />
    </visual>
    <collision>
      <origin rpy="0 1.5708 0" xyz="0 0 0"
      />
      <geometry name="rh_rfknuckle_collision_geom">
        <cylinder length="
  0.014" radius="0.007" />
      </geometry>
    </collision>
  </link>
  <joint
    name="rh_RFJ4" type="revolute">
    <parent link="rh_palm" />
    <child
      link="rh_rfknuckle" />    <!--<origin
    xyz="0.033 0 0.095" rpy="0 0 0" />-->
    <origin rpy="0 0 0" xyz="-0.011 0 0.095" />
    <axis xyz="0 1 0" />
    <limit effort="2" lower="-0.3490658503988659" upper="0.3490658503988659"
      velocity="2.0" />
    <dynamics damping="0.1" />
  </joint>
  <gazebo reference="
  rh_RFJ4">
    <provideFeedback>1</provideFeedback>
    <implicitSpringDamper>1</implicitSpringDamper>
  </gazebo>
  <transmission name="rh_rfknuckle_transmission">
    <type>sr_mechanism_model/SimpleTransmission</type>
    <actuator name="rh_RFJ4">
      <mechanicalReduction>1</mechanicalReduction>
    </actuator>
    <joint name="rh_RFJ4">
      <hardwareInterface>EffortJointInterface</hardwareInterface>
      <hardwareInterface>PositionJointInterface</hardwareInterface>
    </joint>
  </transmission>
  <gazebo reference="rh_rfknuckle">    <!-- knuckle is not
   highly exposed, so bumper is not useful -->
    <material>Gazebo/Grey</material>
  </gazebo>
  <link name="rh_rfproximal">
    <inertial>
      <mass value="
  0.030" />
      <origin xyz="0 0 0.0225" />
      <inertia ixx="0.0000098"
        ixy="0.0" ixz="0.0" iyy="0.00001" iyz="0.0" izz="0.0000018" />
    </inertial>
    <visual>
      <origin rpy="0 0 0" xyz="0 0 0" />
      <geometry name="
  rh_rfproximal_visual">
        <mesh filename="package://sr_description/meshes/components/f_proximal/f_proximal_E3M5.dae"
          scale="0.001 0.001 0.001" />
      </geometry>
      <material name="Grey"
      />
    </visual>
    <collision>
      <origin rpy="0 0 0" xyz="0 0 0.025"
      />
      <geometry name="rh_rfproximal_collision_geom">
        <cylinder length="
  0.040" radius="0.007" />
      </geometry>
    </collision>
  </link>
  <joint
    name="rh_RFJ3" type="revolute">
    <parent link="rh_rfknuckle" />
    <child link="rh_rfproximal" />
    <origin rpy="0 0 0" xyz="0 0 0" />
    <axis xyz="1 0 0" />
    <limit effort="2" lower="-0.2617993877991494"
      upper="1.5707963267948966" velocity="2.0" />
    <dynamics damping="0.1"
    />
  </joint>
  <gazebo reference="rh_RFJ3">
    <provideFeedback>1</provideFeedback>
    <implicitSpringDamper>1</implicitSpringDamper>
  </gazebo>
  <transmission
    name="rh_rfproximal_transmission">
    <type>sr_mechanism_model/SimpleTransmission</type>
    <actuator name="rh_RFJ3">
      <mechanicalReduction>1</mechanicalReduction>
    </actuator>
    <joint name="rh_RFJ3">
      <hardwareInterface>EffortJointInterface</hardwareInterface>
      <hardwareInterface>PositionJointInterface</hardwareInterface>
    </joint>
  </transmission>
  <gazebo reference="rh_rfproximal">
    <selfCollide>true</selfCollide>
  </gazebo>
  <link name="rh_rfmiddle">
    <inertial>
      <origin rpy="
  0 0 0" xyz="0 0 0.0125" />
      <mass value="0.017" />
      <inertia ixx="
  0.0000026" ixy="0.0" ixz="0.0" iyy="0.0000027" iyz="0.0" izz="0.00000087"
      />
    </inertial>
    <visual>
      <origin rpy="0 0 0" xyz="0 0 0" />
      <geometry name="rh_rfmiddle_visual">
        <mesh filename="package://sr_description/meshes/components/f_middle/f_middle_E3M5.dae"
          scale="0.001 0.001 0.001" />
      </geometry>
      <material name="Grey"
      />
    </visual>
    <collision>
      <origin rpy="0 0 0" xyz="0 0 0.0125"
      />
      <geometry name="rh_rfmiddle_collision_geom">
        <cylinder length="
  0.025" radius="0.007" />
      </geometry>
    </collision>
    <collision>
      <origin rpy="0 0 0" xyz="0 0 0.0" />
      <geometry>
        <sphere
          radius="0.007" />
      </geometry>
    </collision>
    <collision>
      <origin rpy="0 0 0" xyz="0 0 0.025" />
      <geometry>
        <sphere
          radius="0.007" />
      </geometry>
    </collision>
  </link>
  <joint name="
  rh_RFJ2" type="revolute">
    <parent link="rh_rfproximal" />
    <child link="
  rh_rfmiddle" />
    <origin rpy="0 0 0" xyz="0 0 0.045" />
    <axis xyz="
  1 0 0" />
    <limit effort="2" lower="0" upper="1.5707963267948966" velocity="
  2.0" />
    <dynamics damping="0.1" />
  </joint>
  <gazebo reference="rh_RFJ2"
  >
    <provideFeedback>1</provideFeedback>
    <implicitSpringDamper>1</implicitSpringDamper>
  </gazebo>
  <transmission name="rh_rfmiddle_transmission">
    <type>sr_mechanism_model/J0Transmission</type>
    <actuator name="rh_RFJ0">
      <mechanicalReduction>1</mechanicalReduction>
    </actuator>
    <joint name="rh_RFJ1">
      <hardwareInterface>EffortJointInterface</hardwareInterface>
      <hardwareInterface>PositionJointInterface</hardwareInterface>
    </joint>
  </transmission>
  <gazebo reference="rh_rfmiddle">
    <selfCollide>true</selfCollide>
  </gazebo>
  <link name="rh_rfdistal">
    <inertial>
      <mass value="
  0.012" />
      <origin xyz="0 0 0.012" />
      <inertia ixx="0.00000094"
        ixy="0.0" ixz="0.0" iyy="0.0000011" iyz="0.0" izz="0.00000053" />
    </inertial>
    <visual>
      <origin rpy="0 0 0" xyz="0 0 0" />
      <geometry name="rh_rfdistal_visual">
        <mesh filename="package://sr_description/meshes/components/f_distal/mst/f_distal_mstXL.dae"
          scale="0.001 0.001 0.001" />
      </geometry>
    </visual>
    <collision>
      <origin rpy="0 0 0" xyz="0 0 0" />
      <geometry name="rh_rfdistal_collision_geom"
      >
        <mesh filename="package://sr_description/meshes/components/f_distal/mst/f_distal_mstXL.dae"
          scale="0.001 0.001 0.001" />
      </geometry>
    </collision>
  </link>
  <joint name="rh_RFJ1" type="revolute">
    <parent link="rh_rfmiddle"
    />
    <child link="rh_rfdistal" />
    <origin rpy="0 0 0" xyz="0 0 0.025"
    />
    <axis xyz="1 0 0" />    <!-- standard distal joint -->
    <limit effort="
  2" lower="0" upper="1.5707963267948966" velocity="2.0" />
    <dynamics damping="
  0.1" />
  </joint>
  <gazebo reference="rh_RFJ1">
    <provideFeedback>1</provideFeedback>
    <implicitSpringDamper>1</implicitSpringDamper>
  </gazebo>
  <link name="
  rh_rftip">
    <inertial>
      <mass value="0.001" />
      <inertia ixx="
  0.0" ixy="0.0" ixz="0.0" iyy="0.0" iyz="0.0" izz="0.0" />
    </inertial>
  </link>
  <joint name="rh_RFtip" type="fixed">
    <parent link="rh_rfdistal"
    />
    <child link="rh_rftip" />
    <origin rpy="0 0 0" xyz="0 0 0.026"
    />
  </joint>
  <link name="rh_rf_mst_link" />
  <joint name="rh_rfdistal_to_mst_joint"
    type="fixed">
    <parent link="rh_rfdistal" />
    <child link="rh_rf_mst_link"
    />
    <origin rpy="0 0 0" xyz="0.0 0.0 0.0" />
  </joint>  <!-- Note that
   all the following transforms were obtained using the script `get_taxel_tfs_from_meshes,py`
          Using the material available in the folders `meshes/f_distal_XL` and
  `meshes/mstXL_distal_isolated_magnets
   -->
  <link name="rh_rf_taxel_0" />
  <joint name="rh_rf_mst_to_taxel_0"
    type="fixed">
    <parent link="rh_rf_mst_link" />
    <child link="rh_rf_taxel_0"
    />
    <origin rpy="-1.51978666 1.44937453e-04 1.45968674"
      xyz="-0.00921687001
   0.00099373239 0.02038228873" />
  </joint>
  <link name="rh_rf_taxel_1" />
  <joint name="rh_rf_mst_to_taxel_1" type="fixed">
    <parent link="rh_rf_mst_link"
    />
    <child link="rh_rf_taxel_1" />
    <origin rpy="-1.59559695 -3.48829319e-04
   2.41934577"
      xyz="-0.00640312645 -0.0065173749 0.018270370759999998" />
  </joint>
  <link name="rh_rf_taxel_2" />
  <joint name="rh_rf_mst_to_taxel_2" type="
  fixed">
    <parent link="rh_rf_mst_link" />
    <child link="rh_rf_taxel_2"
    />
    <origin rpy="-1.65955903 -0.00541627 2.51722701"
      xyz="-0.0066597394100000006
   -0.00576875338 0.01260740369" />
  </joint>
  <link name="rh_rf_taxel_3" />
  <joint name="rh_rf_mst_to_taxel_3" type="fixed">
    <parent link="rh_rf_mst_link"
    />
    <child link="rh_rf_taxel_3" />
    <origin rpy="-1.54268087 6.45535715e-05
   1.40876949"
      xyz="-0.00942467165 0.00123111485 0.013959520520000001" />
  </joint>
  <link name="rh_rf_taxel_4" />
  <joint name="rh_rf_mst_to_taxel_4" type="
  fixed">
    <parent link="rh_rf_mst_link" />
    <child link="rh_rf_taxel_4"
    />
    <origin rpy="-1.29061943 0.00168711 1.52628765"
      xyz="-0.00867928261 0.00090325075
   0.02632664124" />
  </joint>
  <link name="rh_rf_taxel_5" />
  <joint name="
  rh_rf_mst_to_taxel_5" type="fixed">
    <parent link="rh_rf_mst_link" />
    <child link="rh_rf_taxel_5" />
    <origin rpy="-1.19846222 0.08480638 -2.49594701"
      xyz="0.00569565306 -0.00539249259 0.0253778316" />
  </joint>
  <link name="
  rh_rf_taxel_6" />
  <joint name="rh_rf_mst_to_taxel_6" type="fixed">
    <parent
      link="rh_rf_mst_link" />
    <child link="rh_rf_taxel_6" />
    <origin rpy="
  -1.29057253 -0.00189879 -1.52072868"
      xyz="0.00871833126 0.00099431703 0.0261743809"
    />
  </joint>
  <link name="rh_rf_taxel_7" />
  <joint name="rh_rf_mst_to_taxel_7"
    type="fixed">
    <parent link="rh_rf_mst_link" />
    <child link="rh_rf_taxel_7"
    />
    <origin rpy="-1.60361784 5.95662030e-04 -2.40698274"
      xyz="0.00664900914
   -0.00630558868 0.018515388730000002" />
  </joint>
  <link name="rh_rf_taxel_8"
  />
  <joint name="rh_rf_mst_to_taxel_8" type="fixed">
    <parent link="
  rh_rf_mst_link" />
    <child link="rh_rf_taxel_8" />
    <origin rpy="-1.65580869
   1.83052213e-03 -3.13786483"
      xyz="0.00014411317000000002 -0.008049275 0.014931109360000002"
    />
  </joint>
  <link name="rh_rf_taxel_9" />
  <joint name="rh_rf_mst_to_taxel_9"
    type="fixed">
    <parent link="rh_rf_mst_link" />
    <child link="rh_rf_taxel_9"
    />
    <origin rpy="-1.19878812 -0.08458215 2.49544358"
      xyz="-0.0057381420800000004
   -0.0054270967900000005 0.02524200553" />
  </joint>
  <link name="rh_rf_taxel_10"
  />
  <joint name="rh_rf_mst_to_taxel_10" type="fixed">
    <parent link="
  rh_rf_mst_link" />
    <child link="rh_rf_taxel_10" />
    <origin rpy="-1.54285408
   -5.71837391e-05 -1.42527418"
      xyz="0.00942258829 0.00115158208 0.01454831045"
    />
  </joint>
  <link name="rh_rf_taxel_11" />
  <joint name="rh_rf_mst_to_taxel_11"
    type="fixed">
    <parent link="rh_rf_mst_link" />
    <child link="rh_rf_taxel_11"
    />
    <origin rpy="-0.46989731  0.10702183 -1.78833246"
      xyz="0.0038067269 -0.00023025534
   0.03188900555" />
  </joint>
  <link name="rh_rf_taxel_12" />
  <joint name="
  rh_rf_mst_to_taxel_12" type="fixed">
    <parent link="rh_rf_mst_link" />
    <child link="rh_rf_taxel_12" />
    <origin rpy="-0.90945336 -0.00352009
   -3.1076869"
      xyz="2.6127978100000003e-05  -0.00484799149 0.0292631876" />
  </joint>
  <link name="rh_rf_taxel_13" />
  <joint name="rh_rf_mst_to_taxel_13"
    type="fixed">
    <parent link="rh_rf_mst_link" />
    <child link="rh_rf_taxel_13"
    />
    <origin rpy="0.40261749 0.27093248 -1.7070713"
      xyz="-0.00392243091 -5.411787e-05
   0.03187189268" />
  </joint>
  <link name="rh_rf_taxel_14" />
  <joint name="
  rh_rf_mst_to_taxel_14" type="fixed">
    <parent link="rh_rf_mst_link" />
    <child link="rh_rf_taxel_14" />
    <origin rpy="-1.653756 0.00455583 -2.49848336"
      xyz="0.00672575877 -0.0056872052 0.01228742454" />
  </joint>
  <link name="
  rh_rf_taxel_15" />
  <joint name="rh_rf_mst_to_taxel_15" type="fixed">
    <parent link="rh_rf_mst_link" />
    <child link="rh_rf_taxel_15" />
    <origin rpy="-1.52010616 -1.02741516e-04 -1.49088185"
      xyz="0.00919364576 0.00107233058
   0.02073499409" />
  </joint>
  <link name="rh_rf_taxel_16" />
  <joint name="
  rh_rf_mst_to_taxel_16" type="fixed">
    <parent link="rh_rf_mst_link" />
    <child link="rh_rf_taxel_16" />
    <origin rpy="-1.38286616 0.00525309
   -3.12116599"
      xyz="0.00016191958000000002 -0.008007749670000001 0.02215694734"
    />
  </joint>
  <gazebo reference="rh_rfdistal">
    <sensor name="rh_rfdistal_contact"
      type="contact">
      <always_on>1</always_on>
      <update_rate>1000.0</update_rate>
      <contact>
        <collision>rh_rfdistal_collision</collision>
        <topic>rh_rfdistal_collision</topic>
      </contact>
      <plugin filename="
  libgazebo_ros_bumper.so" name="rh_rfdistal_gazebo_ros_bumper_controller">
        <alwaysOn>true</alwaysOn>
        <frameName>rh_rfdistal</frameName>
        <updateRate>100.0</updateRate>
        <bumperTopicName>contacts/rh_rf/distal</bumperTopicName>
      </plugin>
    </sensor>
    <mu1 value="500.0" />
    <mu2 value="500.0"
    />
    <kp value="10000000.0" />
    <kd value="1.0" />
    <selfCollide>true</selfCollide>
  </gazebo>
  <link name="rh_lfmetacarpal">
    <inertial>
      <origin rpy="
  0 0.9599 0" xyz="0.03174867647058824 0 0.02235294117647059" />
      <mass value="
  0.030" />
      <inertia ixx="0.0000145" ixy="0.0" ixz="0.0" iyy="0.00001638"
        iyz="0.0" izz="0.000004272" />
    </inertial>
    <visual>
      <origin
        rpy="0 0.9599 0" xyz="0 0 0" />
      <geometry name="rh_lfmetacarpal_visual"
      >
        <mesh
          filename="package://sr_description/meshes/components/lf_metacarpal/lf_metacarpal_E3M5.dae"
          scale="0.001 0.001 0.001" />
      </geometry>
      <material name="Grey"
      />
    </visual>
    <collision>
      <origin rpy="0 0.9599 0" xyz="0.026986375
   0 0.019" />
      <geometry name="rh_lfmetacarpal_collision_geom">
        <box size="0.018 0.024 0.040" />
      </geometry>
    </collision>
  </link>
  <joint name="rh_LFJ5" type="revolute">
    <parent link="rh_palm" />
    <child link="rh_lfmetacarpal" />
    <origin rpy="0 -0.9599 0" xyz="-0.033
   0 0.02071" />
    <axis xyz="1 0 0" />
    <limit effort="2" lower="0"
      upper="0.7853981633974483" velocity="2.0" />
    <dynamics damping="0.1"
    />
  </joint>
  <gazebo reference="rh_LFJ5">
    <provideFeedback>1</provideFeedback>
    <implicitSpringDamper>1</implicitSpringDamper>
  </gazebo>
  <transmission
    name="rh_lfmetacarpal_transmission">
    <type>sr_mechanism_model/SimpleTransmission</type>
    <actuator name="rh_LFJ5">
      <mechanicalReduction>1</mechanicalReduction>
    </actuator>
    <joint name="rh_LFJ5">
      <hardwareInterface>EffortJointInterface</hardwareInterface>
      <hardwareInterface>PositionJointInterface</hardwareInterface>
    </joint>
  </transmission>
  <gazebo reference="rh_lfmetacarpal">
    <selfCollide>true</selfCollide>
  </gazebo>
  <link name="rh_lfknuckle">
    <inertial>
      <origin rpy="
  0 0 0" xyz="0 0 0" />
      <mass value="0.008" />
      <inertia ixx="0.00000026"
        ixy="0.0" ixz="0.0" iyy="0.00000026" iyz="0.0" izz="0.00000032" />
    </inertial>
    <visual>
      <origin rpy="0 0 0" xyz="0 0 0.0005" />
      <geometry name="rh_lfknuckle_visual">
        <mesh filename="package://sr_description/meshes/components/f_knuckle/f_knuckle_E3M5.dae"
          scale="0.001 0.001 0.001" />
      </geometry>
      <material name="LightGrey"
      />
    </visual>
    <collision>
      <origin rpy="0 1.5708 0" xyz="0 0 0"
      />
      <geometry name="rh_lfknuckle_collision_geom">
        <cylinder length="
  0.014" radius="0.007" />
      </geometry>
    </collision>
  </link>
  <joint
    name="rh_LFJ4" type="revolute">
    <parent link="rh_lfmetacarpal" />
    <child link="rh_lfknuckle" />    <!--<origin
    xyz="0.033 0 0.095" rpy="
  0 0 0" />-->
    <origin rpy="0 0.9599 0" xyz="0.05397275 0 0.03779463" />
    <axis xyz="0 1 0" />
    <limit effort="2" lower="-0.3490658503988659"
      upper="0.3490658503988659" velocity="2.0" />
    <dynamics damping="0.1"
    />
  </joint>
  <gazebo reference="rh_LFJ4">
    <provideFeedback>1</provideFeedback>
    <implicitSpringDamper>1</implicitSpringDamper>
  </gazebo>
  <transmission
    name="rh_lfknuckle_transmission">
    <type>sr_mechanism_model/SimpleTransmission</type>
    <actuator name="rh_LFJ4">
      <mechanicalReduction>1</mechanicalReduction>
    </actuator>
    <joint name="rh_LFJ4">
      <hardwareInterface>EffortJointInterface</hardwareInterface>
      <hardwareInterface>PositionJointInterface</hardwareInterface>
    </joint>
  </transmission>
  <gazebo reference="rh_lfknuckle">    <!-- knuckle is not
   highly exposed, so bumper is not useful -->
    <material>Gazebo/Grey</material>
  </gazebo>
  <link name="rh_lfproximal">
    <inertial>
      <mass value="
  0.030" />
      <origin xyz="0 0 0.0225" />
      <inertia ixx="0.0000098"
        ixy="0.0" ixz="0.0" iyy="0.00001" iyz="0.0" izz="0.0000018" />
    </inertial>
    <visual>
      <origin rpy="0 0 0" xyz="0 0 0" />
      <geometry name="
  rh_lfproximal_visual">
        <mesh filename="package://sr_description/meshes/components/f_proximal/f_proximal_E3M5.dae"
          scale="0.001 0.001 0.001" />
      </geometry>
      <material name="Grey"
      />
    </visual>
    <collision>
      <origin rpy="0 0 0" xyz="0 0 0.025"
      />
      <geometry name="rh_lfproximal_collision_geom">
        <cylinder length="
  0.040" radius="0.007" />
      </geometry>
    </collision>
  </link>
  <joint
    name="rh_LFJ3" type="revolute">
    <parent link="rh_lfknuckle" />
    <child link="rh_lfproximal" />
    <origin rpy="0 0 0" xyz="0 0 0" />
    <axis xyz="1 0 0" />
    <limit effort="2" lower="-0.2617993877991494"
      upper="1.5707963267948966" velocity="2.0" />
    <dynamics damping="0.1"
    />
  </joint>
  <gazebo reference="rh_LFJ3">
    <provideFeedback>1</provideFeedback>
    <implicitSpringDamper>1</implicitSpringDamper>
  </gazebo>
  <transmission
    name="rh_lfproximal_transmission">
    <type>sr_mechanism_model/SimpleTransmission</type>
    <actuator name="rh_LFJ3">
      <mechanicalReduction>1</mechanicalReduction>
    </actuator>
    <joint name="rh_LFJ3">
      <hardwareInterface>EffortJointInterface</hardwareInterface>
      <hardwareInterface>PositionJointInterface</hardwareInterface>
    </joint>
  </transmission>
  <gazebo reference="rh_lfproximal">
    <selfCollide>true</selfCollide>
  </gazebo>
  <link name="rh_lfmiddle">
    <inertial>
      <origin rpy="
  0 0 0" xyz="0 0 0.0125" />
      <mass value="0.017" />
      <inertia ixx="
  0.0000026" ixy="0.0" ixz="0.0" iyy="0.0000027" iyz="0.0" izz="0.00000087"
      />
    </inertial>
    <visual>
      <origin rpy="0 0 0" xyz="0 0 0" />
      <geometry name="rh_lfmiddle_visual">
        <mesh filename="package://sr_description/meshes/components/f_middle/f_middle_E3M5.dae"
          scale="0.001 0.001 0.001" />
      </geometry>
      <material name="Grey"
      />
    </visual>
    <collision>
      <origin rpy="0 0 0" xyz="0 0 0.0125"
      />
      <geometry name="rh_lfmiddle_collision_geom">
        <cylinder length="
  0.025" radius="0.007" />
      </geometry>
    </collision>
    <collision>
      <origin rpy="0 0 0" xyz="0 0 0.0" />
      <geometry>
        <sphere
          radius="0.007" />
      </geometry>
    </collision>
    <collision>
      <origin rpy="0 0 0" xyz="0 0 0.025" />
      <geometry>
        <sphere
          radius="0.007" />
      </geometry>
    </collision>
  </link>
  <joint name="
  rh_LFJ2" type="revolute">
    <parent link="rh_lfproximal" />
    <child link="
  rh_lfmiddle" />
    <origin rpy="0 0 0" xyz="0 0 0.045" />
    <axis xyz="
  1 0 0" />
    <limit effort="2" lower="0" upper="1.5707963267948966" velocity="
  2.0" />
    <dynamics damping="0.1" />
  </joint>
  <gazebo reference="rh_LFJ2"
  >
    <provideFeedback>1</provideFeedback>
    <implicitSpringDamper>1</implicitSpringDamper>
  </gazebo>
  <transmission name="rh_lfmiddle_transmission">
    <type>sr_mechanism_model/J0Transmission</type>
    <actuator name="rh_LFJ0">
      <mechanicalReduction>1</mechanicalReduction>
    </actuator>
    <joint name="rh_LFJ1">
      <hardwareInterface>EffortJointInterface</hardwareInterface>
      <hardwareInterface>PositionJointInterface</hardwareInterface>
    </joint>
  </transmission>
  <gazebo reference="rh_lfmiddle">
    <selfCollide>true</selfCollide>
  </gazebo>
  <link name="rh_lfdistal">
    <inertial>
      <mass value="
  0.012" />
      <origin xyz="0 0 0.012" />
      <inertia ixx="0.00000094"
        ixy="0.0" ixz="0.0" iyy="0.0000011" iyz="0.0" izz="0.00000053" />
    </inertial>
    <visual>
      <origin rpy="0 0 0" xyz="0 0 0" />
      <geometry name="rh_lfdistal_visual">
        <mesh filename="package://sr_description/meshes/components/f_distal/mst/f_distal_mstXL.dae"
          scale="0.001 0.001 0.001" />
      </geometry>
    </visual>
    <collision>
      <origin rpy="0 0 0" xyz="0 0 0" />
      <geometry name="rh_lfdistal_collision_geom"
      >
        <mesh filename="package://sr_description/meshes/components/f_distal/mst/f_distal_mstXL.dae"
          scale="0.001 0.001 0.001" />
      </geometry>
    </collision>
  </link>
  <joint name="rh_LFJ1" type="revolute">
    <parent link="rh_lfmiddle"
    />
    <child link="rh_lfdistal" />
    <origin rpy="0 0 0" xyz="0 0 0.025"
    />
    <axis xyz="1 0 0" />    <!-- standard distal joint -->
    <limit effort="
  2" lower="0" upper="1.5707963267948966" velocity="2.0" />
    <dynamics damping="
  0.1" />
  </joint>
  <gazebo reference="rh_LFJ1">
    <provideFeedback>1</provideFeedback>
    <implicitSpringDamper>1</implicitSpringDamper>
  </gazebo>
  <link name="
  rh_lftip">
    <inertial>
      <mass value="0.001" />
      <inertia ixx="
  0.0" ixy="0.0" ixz="0.0" iyy="0.0" iyz="0.0" izz="0.0" />
    </inertial>
  </link>
  <joint name="rh_LFtip" type="fixed">
    <parent link="rh_lfdistal"
    />
    <child link="rh_lftip" />
    <origin rpy="0 0 0" xyz="0 0 0.026"
    />
  </joint>
  <link name="rh_lf_mst_link" />
  <joint name="rh_lfdistal_to_mst_joint"
    type="fixed">
    <parent link="rh_lfdistal" />
    <child link="rh_lf_mst_link"
    />
    <origin rpy="0 0 0" xyz="0.0 0.0 0.0" />
  </joint>  <!-- Note that
   all the following transforms were obtained using the script `get_taxel_tfs_from_meshes,py`
          Using the material available in the folders `meshes/f_distal_XL` and
  `meshes/mstXL_distal_isolated_magnets
   -->
  <link name="rh_lf_taxel_0" />
  <joint name="rh_lf_mst_to_taxel_0"
    type="fixed">
    <parent link="rh_lf_mst_link" />
    <child link="rh_lf_taxel_0"
    />
    <origin rpy="-1.51978666 1.44937453e-04 1.45968674"
      xyz="-0.00921687001
   0.00099373239 0.02038228873" />
  </joint>
  <link name="rh_lf_taxel_1" />
  <joint name="rh_lf_mst_to_taxel_1" type="fixed">
    <parent link="rh_lf_mst_link"
    />
    <child link="rh_lf_taxel_1" />
    <origin rpy="-1.59559695 -3.48829319e-04
   2.41934577"
      xyz="-0.00640312645 -0.0065173749 0.018270370759999998" />
  </joint>
  <link name="rh_lf_taxel_2" />
  <joint name="rh_lf_mst_to_taxel_2" type="
  fixed">
    <parent link="rh_lf_mst_link" />
    <child link="rh_lf_taxel_2"
    />
    <origin rpy="-1.65955903 -0.00541627 2.51722701"
      xyz="-0.0066597394100000006
   -0.00576875338 0.01260740369" />
  </joint>
  <link name="rh_lf_taxel_3" />
  <joint name="rh_lf_mst_to_taxel_3" type="fixed">
    <parent link="rh_lf_mst_link"
    />
    <child link="rh_lf_taxel_3" />
    <origin rpy="-1.54268087 6.45535715e-05
   1.40876949"
      xyz="-0.00942467165 0.00123111485 0.013959520520000001" />
  </joint>
  <link name="rh_lf_taxel_4" />
  <joint name="rh_lf_mst_to_taxel_4" type="
  fixed">
    <parent link="rh_lf_mst_link" />
    <child link="rh_lf_taxel_4"
    />
    <origin rpy="-1.29061943 0.00168711 1.52628765"
      xyz="-0.00867928261 0.00090325075
   0.02632664124" />
  </joint>
  <link name="rh_lf_taxel_5" />
  <joint name="
  rh_lf_mst_to_taxel_5" type="fixed">
    <parent link="rh_lf_mst_link" />
    <child link="rh_lf_taxel_5" />
    <origin rpy="-1.19846222 0.08480638 -2.49594701"
      xyz="0.00569565306 -0.00539249259 0.0253778316" />
  </joint>
  <link name="
  rh_lf_taxel_6" />
  <joint name="rh_lf_mst_to_taxel_6" type="fixed">
    <parent
      link="rh_lf_mst_link" />
    <child link="rh_lf_taxel_6" />
    <origin rpy="
  -1.29057253 -0.00189879 -1.52072868"
      xyz="0.00871833126 0.00099431703 0.0261743809"
    />
  </joint>
  <link name="rh_lf_taxel_7" />
  <joint name="rh_lf_mst_to_taxel_7"
    type="fixed">
    <parent link="rh_lf_mst_link" />
    <child link="rh_lf_taxel_7"
    />
    <origin rpy="-1.60361784 5.95662030e-04 -2.40698274"
      xyz="0.00664900914
   -0.00630558868 0.018515388730000002" />
  </joint>
  <link name="rh_lf_taxel_8"
  />
  <joint name="rh_lf_mst_to_taxel_8" type="fixed">
    <parent link="
  rh_lf_mst_link" />
    <child link="rh_lf_taxel_8" />
    <origin rpy="-1.65580869
   1.83052213e-03 -3.13786483"
      xyz="0.00014411317000000002 -0.008049275 0.014931109360000002"
    />
  </joint>
  <link name="rh_lf_taxel_9" />
  <joint name="rh_lf_mst_to_taxel_9"
    type="fixed">
    <parent link="rh_lf_mst_link" />
    <child link="rh_lf_taxel_9"
    />
    <origin rpy="-1.19878812 -0.08458215 2.49544358"
      xyz="-0.0057381420800000004
   -0.0054270967900000005 0.02524200553" />
  </joint>
  <link name="rh_lf_taxel_10"
  />
  <joint name="rh_lf_mst_to_taxel_10" type="fixed">
    <parent link="
  rh_lf_mst_link" />
    <child link="rh_lf_taxel_10" />
    <origin rpy="-1.54285408
   -5.71837391e-05 -1.42527418"
      xyz="0.00942258829 0.00115158208 0.01454831045"
    />
  </joint>
  <link name="rh_lf_taxel_11" />
  <joint name="rh_lf_mst_to_taxel_11"
    type="fixed">
    <parent link="rh_lf_mst_link" />
    <child link="rh_lf_taxel_11"
    />
    <origin rpy="-0.46989731  0.10702183 -1.78833246"
      xyz="0.0038067269 -0.00023025534
   0.03188900555" />
  </joint>
  <link name="rh_lf_taxel_12" />
  <joint name="
  rh_lf_mst_to_taxel_12" type="fixed">
    <parent link="rh_lf_mst_link" />
    <child link="rh_lf_taxel_12" />
    <origin rpy="-0.90945336 -0.00352009
   -3.1076869"
      xyz="2.6127978100000003e-05  -0.00484799149 0.0292631876" />
  </joint>
  <link name="rh_lf_taxel_13" />
  <joint name="rh_lf_mst_to_taxel_13"
    type="fixed">
    <parent link="rh_lf_mst_link" />
    <child link="rh_lf_taxel_13"
    />
    <origin rpy="0.40261749 0.27093248 -1.7070713"
      xyz="-0.00392243091 -5.411787e-05
   0.03187189268" />
  </joint>
  <link name="rh_lf_taxel_14" />
  <joint name="
  rh_lf_mst_to_taxel_14" type="fixed">
    <parent link="rh_lf_mst_link" />
    <child link="rh_lf_taxel_14" />
    <origin rpy="-1.653756 0.00455583 -2.49848336"
      xyz="0.00672575877 -0.0056872052 0.01228742454" />
  </joint>
  <link name="
  rh_lf_taxel_15" />
  <joint name="rh_lf_mst_to_taxel_15" type="fixed">
    <parent link="rh_lf_mst_link" />
    <child link="rh_lf_taxel_15" />
    <origin rpy="-1.52010616 -1.02741516e-04 -1.49088185"
      xyz="0.00919364576 0.00107233058
   0.02073499409" />
  </joint>
  <link name="rh_lf_taxel_16" />
  <joint name="
  rh_lf_mst_to_taxel_16" type="fixed">
    <parent link="rh_lf_mst_link" />
    <child link="rh_lf_taxel_16" />
    <origin rpy="-1.38286616 0.00525309
   -3.12116599"
      xyz="0.00016191958000000002 -0.008007749670000001 0.02215694734"
    />
  </joint>
  <gazebo reference="rh_lfdistal">
    <sensor name="rh_lfdistal_contact"
      type="contact">
      <always_on>1</always_on>
      <update_rate>1000.0</update_rate>
      <contact>
        <collision>rh_lfdistal_collision</collision>
        <topic>rh_lfdistal_collision</topic>
      </contact>
      <plugin filename="
  libgazebo_ros_bumper.so" name="rh_lfdistal_gazebo_ros_bumper_controller">
        <alwaysOn>true</alwaysOn>
        <frameName>rh_lfdistal</frameName>
        <updateRate>100.0</updateRate>
        <bumperTopicName>contacts/rh_lf/distal</bumperTopicName>
      </plugin>
    </sensor>
    <mu1 value="500.0" />
    <mu2 value="500.0"
    />
    <kp value="10000000.0" />
    <kd value="1.0" />
    <selfCollide>true</selfCollide>
  </gazebo>
  <link name="rh_thbase">
    <inertial>
      <mass value="
  0.010" />
      <origin rpy="0 0 0" xyz="0 0 0" />
      <inertia ixx="0.00000016"
        ixy="0.0" ixz="0.0" iyy="0.00000016" iyz="0.0" izz="0.00000016" />
    </inertial>
    <visual>
      <origin rpy="0 0 0" xyz="0 0 0" />
      <geometry name="rh_thbase_visual">
        <box size="0.001 0.001 0.001"
        />
      </geometry>
      <material name="shadow_thbase_material">
        <color rgba="0.5 0.5 0.5 1.0" />
      </material>
    </visual>
    <collision>
      <origin rpy="0 0 0" xyz="0 0 0" />
      <geometry name="rh_thbase_collision_geom"
      >
        <sphere radius="0.011" />
      </geometry>
    </collision>
  </link>
  <joint name="rh_THJ5" type="revolute">
    <parent link="rh_palm" />
    <child link="rh_thbase" />
    <origin rpy="-0.7853981633974483 0 -1.5707963267948966"
      xyz="0.034 -0.00858 0.029" />
    <axis xyz="0 0 -1" />
    <limit effort="
  5.0" lower="-1.0471975511965976" upper="1.0471975511965976" velocity="4.0"
    />
    <dynamics damping="0.2" />
  </joint>
  <gazebo reference="rh_THJ5"
  >
    <provideFeedback>1</provideFeedback>
    <implicitSpringDamper>1</implicitSpringDamper>
  </gazebo>
  <transmission name="rh_thbase_transmission">
    <type>sr_mechanism_model/SimpleTransmission</type>
    <actuator name="rh_THJ5">
      <mechanicalReduction>1</mechanicalReduction>
    </actuator>
    <joint name="rh_THJ5">
      <hardwareInterface>EffortJointInterface</hardwareInterface>
      <hardwareInterface>PositionJointInterface</hardwareInterface>
    </joint>
  </transmission>
  <gazebo reference="rh_thbase">    <!-- base is inside
   the proximal and not exposed, so bumper is not needed -->
    <selfCollide>false</selfCollide>
  </gazebo>
  <link name="rh_thproximal">
    <inertial>
      <mass value="
  0.040" />
      <origin rpy="0 0 0" xyz="0 0 0.019" />
      <inertia ixx="
  0.0000136" ixy="0.0" ixz="0.0" iyy="0.0000136" iyz="0.0" izz="0.00000313"
      />
    </inertial>
    <visual>
      <origin rpy="0 0 1.5707963267948966"
        xyz="0 0 0" />
      <geometry name="rh_thproximal_visual">
        <mesh
          filename="package://sr_description/meshes/components/th_proximal/th_proximal_E3M5.dae"
          scale="0.001 0.001 0.001" />
      </geometry>
      <material name="shadow_thproximal_material"
      >
        <color rgba="0.2 0.2 0.2 1.0" />
      </material>
    </visual>
    <collision>
      <origin rpy="0 0 0" xyz="0 0 0.020" />
      <geometry
        name="rh_thproximal_collision_geom">
        <cylinder length="0.018" radius="
  0.012" />
      </geometry>
    </collision>
  </link>
  <joint name="rh_THJ4"
    type="revolute">
    <parent link="rh_thbase" />
    <child link="rh_thproximal"
    />
    <origin rpy="0 0 0" xyz="0 0 0" />
    <axis xyz="0 1 0" />
    <limit
      effort="3" lower="0.0" upper="1.2217304763960306" velocity="4.0" />
    <dynamics damping="0.2" />
  </joint>
  <gazebo reference="rh_THJ4">
    <provideFeedback>1</provideFeedback>
    <implicitSpringDamper>1</implicitSpringDamper>
  </gazebo>
  <transmission name="rh_thproximal_transmission">
    <type>sr_mechanism_model/SimpleTransmission</type>
    <actuator name="rh_THJ4">
      <mechanicalReduction>1</mechanicalReduction>
    </actuator>
    <joint name="rh_THJ4">
      <hardwareInterface>EffortJointInterface</hardwareInterface>
      <hardwareInterface>PositionJointInterface</hardwareInterface>
    </joint>
  </transmission>
  <gazebo reference="rh_thproximal">
    <selfCollide>false</selfCollide>
  </gazebo>
  <link name="rh_thhub">
    <inertial>
      <mass value="0.005"
      />
      <origin rpy="0 0 0" xyz="0 0 0" />
      <inertia ixx="0.000001"
        ixy="0.0" ixz="0.0" iyy="0.000001" iyz="0.0" izz="0.0000003" />
    </inertial>
    <visual>
      <origin rpy="0 0 0" xyz="0 0 0" />
      <geometry name="rh_thhub_visual">
        <box size="0.001 0.001 0.001" />
      </geometry>
      <material name="shadow_thhub_material">
        <color
          rgba="0.7 0.7 0.7 1.0" />
      </material>
    </visual>
    <collision>
      <origin rpy="0 0 0" xyz="0 0 0" />
      <geometry name="rh_thhub_collision_geom"
      >
        <sphere radius="0.010" />
      </geometry>
    </collision>
  </link>
  <joint name="rh_THJ3" type="revolute">
    <parent link="rh_thproximal"
    />
    <child link="rh_thhub" />
    <origin rpy="0 0 0" xyz="0 0 0.038"
    />
    <axis xyz="0 1 0" />
    <limit effort="2.0" lower="-0.20943951023931953"
      upper="0.20943951023931953" velocity="4.0" />
    <dynamics damping="0.2"
    />
  </joint>
  <gazebo reference="rh_THJ3">
    <provideFeedback>1</provideFeedback>
    <implicitSpringDamper>1</implicitSpringDamper>
  </gazebo>
  <transmission
    name="rh_thhub_transmission">
    <type>sr_mechanism_model/SimpleTransmission</type>
    <actuator name="rh_THJ3">
      <mechanicalReduction>1</mechanicalReduction>
    </actuator>
    <joint name="rh_THJ3">
      <hardwareInterface>EffortJointInterface</hardwareInterface>
      <hardwareInterface>PositionJointInterface</hardwareInterface>
    </joint>
  </transmission>
  <gazebo reference="rh_thhub">    <!-- hub is inside the
   proximal and not exposed, so bumper is not needed -->
    <selfCollide>false</selfCollide>
  </gazebo>
  <link name="rh_thmiddle">
    <inertial>
      <mass value="
  0.020" />
      <origin rpy="0 0 0" xyz="0 0 0.016" />
      <inertia ixx="
  0.0000051" ixy="0.0" ixz="0.0" iyy="0.0000051" iyz="0.0" izz="0.00000121"
      />
    </inertial>
    <visual>
      <origin rpy="0 0 1.5707963267948966"
        xyz="0 0 0" />
      <geometry name="rh_thmiddle_visual">
        <mesh filename="
  package://sr_description/meshes/components/th_middle/th_middle_E3M5.dae"
          scale="
  0.001 0.001 0.001" />
      </geometry>
      <material name="shadow_thmiddle_material"
      >
        <color rgba="0.2 0.2 0.2 1.0" />
      </material>
    </visual>
    <collision>
      <origin rpy="0 0 0" xyz="0 0 0.012" />
      <geometry
        name="rh_thmiddle_collision_geom">
        <cylinder length="0.018" radius="
  0.011" />
      </geometry>
    </collision>
    <collision>
      <origin rpy="
  0 0 0" xyz="0 0 0.019" />
      <geometry>
        <sphere radius="0.011"
        />
      </geometry>
    </collision>
    <collision>
      <origin rpy="0
   1.5708 0" xyz="0 0 0.032" />
      <geometry>
        <cylinder length="
  0.014" radius="0.010" />
      </geometry>
    </collision>
  </link>
  <joint
    name="rh_THJ2" type="revolute">
    <parent link="rh_thhub" />
    <child
      link="rh_thmiddle" />
    <origin rpy="0 0 0" xyz="0 0 0" />
    <axis xyz="
  1 0 0" />
    <limit effort="2.0" lower="-0.6981317007977318" upper="0.6981317007977318"
      velocity="2.0" />
    <dynamics damping="0.1" />
  </joint>
  <gazebo reference="
  rh_THJ2">
    <provideFeedback>1</provideFeedback>
    <implicitSpringDamper>1</implicitSpringDamper>
  </gazebo>
  <transmission name="rh_thmiddle_transmission">
    <type>sr_mechanism_model/SimpleTransmission</type>
    <actuator name="rh_THJ2">
      <mechanicalReduction>1</mechanicalReduction>
    </actuator>
    <joint name="rh_THJ2">
      <hardwareInterface>EffortJointInterface</hardwareInterface>
      <hardwareInterface>PositionJointInterface</hardwareInterface>
    </joint>
  </transmission>
  <gazebo reference="rh_thmiddle"> </gazebo>  <!-- common
   -->
  <link name="rh_thdistal">
    <inertial>
      <mass value="0.016"
      />
      <origin rpy="0 0 0" xyz="0 0 0.01375" />
      <inertia ixx="0.0000021"
        ixy="0.0" ixz="0.0" iyy="0.0000022" iyz="0.0" izz="0.000001" />
    </inertial>
    <visual>
      <origin rpy="0 0 0" xyz="0 0 0" />
      <geometry name="rh_thdistal_visual">
        <mesh filename="package://sr_description/meshes/components/th_distal/mst/th_distal_mst.dae"
          scale="0.001 0.001 0.001" />
      </geometry>
      <material name="shadow_thmiddle_material"
      >
        <color rgba="0.2 0.2 0.2 1.0" />
      </material>
    </visual>
    <collision>
      <origin rpy="0 0 0" xyz="0 0 0" />
      <geometry name="
  rh_thmiddle_collision_geom">
        <mesh filename="package://sr_description/meshes/components/th_distal/mst/th_distal_mst.dae"
          scale="0.001 0.001 0.001" />
      </geometry>
    </collision>
  </link>
  <joint name="rh_THJ1" type="revolute">
    <parent link="rh_thmiddle"
    />
    <child link="rh_thdistal" />
    <origin rpy="0 0 0" xyz="0 0 0.032"
    />
    <axis xyz="1 0 0" />
    <limit effort="1.0" lower="-0.2617993877991494"
      upper="1.5707963267948966" velocity="4.0" />
    <dynamics damping="0.2"
    />
  </joint>
  <gazebo reference="rh_THJ1">
    <provideFeedback>1</provideFeedback>
    <implicitSpringDamper>1</implicitSpringDamper>
  </gazebo>
  <link name="
  rh_thtip">
    <inertial>
      <mass value="0.001" />
      <inertia ixx="
  0.0" ixy="0.0" ixz="0.0" iyy="0.0" iyz="0.0" izz="0.0" />
    </inertial>
  </link>
  <joint name="rh_thtip" type="fixed">
    <parent link="rh_thdistal"
    />
    <child link="rh_thtip" />
    <origin rpy="0 0 0" xyz="0 0 0.0275"
    />
  </joint>
  <link name="rh_th_mst_link" />
  <joint name="rh_thdistal_to_mst_joint"
    type="fixed">
    <parent link="rh_thdistal" />
    <child link="rh_th_mst_link"
    />
    <origin rpy="0 0 0" xyz="0.0 0.0 0.0" />
  </joint>  <!-- Note that
   all the following transforms were obtained using the script `get_taxel_tfs_from_meshes,py`
          Using the material available in the folders `meshes/th_distal` and
  `meshes/mst_thumb_isolated_magnets
   -->
  <link name="rh_th_taxel_0" />
  <joint name="rh_th_mst_to_taxel_0"
    type="fixed">
    <parent link="rh_th_mst_link" />
    <child link="rh_th_taxel_0"
    />
    <origin rpy="-1.44982585 -2.08115741e-04 1.59945065"
      xyz="-0.00972933972
   6.547063e-05 0.023220305440000002" />
  </joint>
  <link name="rh_th_taxel_1"
  />
  <joint name="rh_th_mst_to_taxel_1" type="fixed">
    <parent link="
  rh_th_mst_link" />
    <child link="rh_th_taxel_1" />
    <origin rpy="-1.51571209
   -1.67398077e-03 2.40655807"
      xyz="-0.00678859029 -0.00682804277 0.022168204769999998"
    />
  </joint>
  <link name="rh_th_taxel_2" />
  <joint name="rh_th_mst_to_taxel_2"
    type="fixed">
    <parent link="rh_th_mst_link" />
    <child link="rh_th_taxel_2"
    />
    <origin rpy="-1.57147269 -2.79611809e-07 2.50079482"
      xyz="-0.00683900328
   -0.006980068880000001 0.01567987087" />
  </joint>
  <link name="rh_th_taxel_3"
  />
  <joint name="rh_th_mst_to_taxel_3" type="fixed">
    <parent link="
  rh_th_mst_link" />
    <child link="rh_th_taxel_3" />
    <origin rpy="-1.49660488
   -4.46852287e-06 1.57242485"
      xyz="-0.01033255406 -0.00019997814999999999 0.01695037225"
    />
  </joint>
  <link name="rh_th_taxel_4" />
  <joint name="rh_th_mst_to_taxel_4"
    type="fixed">
    <parent link="rh_th_mst_link" />
    <child link="rh_th_taxel_4"
    />
    <origin rpy="-1.31451327 9.71895171e-04 1.54029857"
      xyz="-0.0087115137
   0.0006830358600000001 0.029743822479999998" />
  </joint>
  <link name="rh_th_taxel_5"
  />
  <joint name="rh_th_mst_to_taxel_5" type="fixed">
    <parent link="
  rh_th_mst_link" />
    <child link="rh_th_taxel_5" />
    <origin rpy="-1.2130077
   0.0791523 -2.49904124"
      xyz="0.00584283536 -0.005754435390000001 0.028414353479999998"
    />
  </joint>
  <link name="rh_th_taxel_6" />
  <joint name="rh_th_mst_to_taxel_6"
    type="fixed">
    <parent link="rh_th_mst_link" />
    <child link="rh_th_taxel_6"
    />
    <origin rpy="-1.32724314 -6.92015708e-04 -1.54681168"
      xyz="0.00874332376
   0.0006870560700000001 0.02962382328" />
  </joint>
  <link name="rh_th_taxel_7"
  />
  <joint name="rh_th_mst_to_taxel_7" type="fixed">
    <parent link="
  rh_th_mst_link" />
    <child link="rh_th_taxel_7" />
    <origin rpy="-1.51525482
   1.66235999e-03 -2.39488770"
      xyz="0.0067865684899999995 -0.00688211391 0.02151390819"
    />
  </joint>
  <link name="rh_th_taxel_8" />
  <joint name="rh_th_mst_to_taxel_8"
    type="fixed">
    <parent link="rh_th_mst_link" />
    <child link="rh_th_taxel_8"
    />
    <origin rpy="-1.61454367  0.00471267 -3.13119361"
      xyz="3.874778e-05 -0.008949864160000001
   0.01831621862" />
  </joint>
  <link name="rh_th_taxel_9" />
  <joint name="
  rh_th_mst_to_taxel_9" type="fixed">
    <parent link="rh_th_mst_link" />
    <child link="rh_th_taxel_9" />
    <origin rpy="-1.20741111 -0.08271541
   2.50644614"
      xyz="-0.00602973412 -0.00557533839 0.02851725326" />
  </joint>
  <link name="rh_th_taxel_10" />
  <joint name="rh_th_mst_to_taxel_10" type="
  fixed">
    <parent link="rh_th_mst_link" />
    <child link="rh_th_taxel_10"
    />
    <origin rpy="-1.49973096 1.77031295e-06 -1.57149935"
      xyz="0.01031795085
   -5.661189e-05 0.01718739188" />
  </joint>
  <link name="rh_th_taxel_11" />
  <joint name="rh_th_mst_to_taxel_11" type="fixed">
    <parent link="rh_th_mst_link"
    />
    <child link="rh_th_taxel_11" />
    <origin rpy="-0.48614961 -0.01851918
   -1.53146519"
      xyz="0.00427101443 0.00133447037 0.035393853360000005" />
  </joint>
  <link name="rh_th_taxel_12" />
  <joint name="rh_th_mst_to_taxel_12" type="
  fixed">
    <parent link="rh_th_mst_link" />
    <child link="rh_th_taxel_12"
    />
    <origin rpy="-0.91769616 -0.00387778 -3.10187213"
      xyz="0.00044288174000000003
    -0.00490763679 0.03287451239" />
  </joint>
  <link name="rh_th_taxel_13"
  />
  <joint name="rh_th_mst_to_taxel_13" type="fixed">
    <parent link="
  rh_th_mst_link" />
    <child link="rh_th_taxel_13" />
    <origin rpy="0.57255288
   -0.05296773 -1.55204906"
      xyz="-0.00476176569 0.00133320954 0.03510656598" />
  </joint>
  <link name="rh_th_taxel_14" />
  <joint name="rh_th_mst_to_taxel_14"
    type="fixed">
    <parent link="rh_th_mst_link" />
    <child link="rh_th_taxel_14"
    />
    <origin rpy="-1.57796384 3.55764306e-05 -2.51646538"
      xyz="0.006777310250000001
   -0.007027842330000001 0.01588156097" />
  </joint>
  <link name="rh_th_taxel_15"
  />
  <joint name="rh_th_mst_to_taxel_15" type="fixed">
    <parent link="
  rh_th_mst_link" />
    <child link="rh_th_taxel_15" />
    <origin rpy="-1.45016104
   1.12707339e-04 -1.58640662"
      xyz="0.00976721312 0.00018196067 0.02293966039"
    />
  </joint>
  <link name="rh_th_taxel_16" />
  <joint name="rh_th_mst_to_taxel_16"
    type="fixed">
    <parent link="rh_th_mst_link" />
    <child link="rh_th_taxel_16"
    />
    <origin rpy="-1.34351864 0.00345266 -3.12631207"
      xyz="0.00022809436 -0.00853802427
   0.02466986776" />
  </joint>
  <gazebo reference="rh_thdistal">
    <sensor
      name="rh_thdistal_contact" type="contact">
      <always_on>1</always_on>
      <update_rate>1000.0</update_rate>
      <contact>
        <collision>rh_thdistal_collision</collision>
        <topic>rh_thdistal_collision</topic>
      </contact>
      <plugin filename="
  libgazebo_ros_bumper.so" name="rh_thdistal_gazebo_ros_bumper_controller">
        <alwaysOn>true</alwaysOn>
        <frameName>rh_thdistal</frameName>
        <updateRate>100.0</updateRate>
        <bumperTopicName>contacts/rh_th/distal</bumperTopicName>
      </plugin>
    </sensor>
    <mu1 value="500.0" />
    <mu2 value="500.0"
    />
    <kp value="10000000.0" />
    <kd value="1.0" />
    <selfCollide>true</selfCollide>
  </gazebo>
  <transmission name="rh_thdistal_transmission">
    <type>sr_mechanism_model/SimpleTransmission</type>
    <actuator name="rh_THJ1">
      <mechanicalReduction>1</mechanicalReduction>
    </actuator>
    <joint name="rh_THJ1">
      <hardwareInterface>EffortJointInterface</hardwareInterface>
      <hardwareInterface>PositionJointInterface</hardwareInterface>
    </joint>
  </transmission>
</robot>