<mujoco model="shadow_hand">
    <compiler autolimits="true" angle="radian" meshdir="new_assets"/>
    <option impratio="10" cone="elliptic" />
    <default>
        <default class="right_hand">
            <mesh scale="0.001 0.001 0.001" />
            <joint axis="1 0 0" armature="0.00020000000000000001" damping="0.050000000000000003"
                frictionloss="0.01" />
            <position forcerange="-1 1" />
            <default class="wrist">
                <joint damping="0.5" />
                <default class="wrist_y">
                    <joint axis="0 1 0" range="-0.48899999999999999 0.17399999999999999" />
                    <position ctrlrange="-0.52359900000000004 0.17453299999999999"
                        forcerange="-10 10" kp="10" />
                </default>
                <default class="wrist_x">
                    <joint range="-0.69813199999999997 0.48869200000000002" />
                    <position ctrlrange="-0.69813199999999997 0.48869200000000002"
                        forcerange="-5 5" kp="8" />
                </default>
            </default>
            <default class="thumb">
                <default class="thbase">
                    <joint axis="0 0 -1" range="-1.0471999999999999 1.0471999999999999" />
                    <position ctrlrange="-1.0471999999999999 1.0471999999999999"
                        forcerange="-3 3" kp="0.40000000000000002" />
                </default>
                <default class="thproximal">
                    <joint range="0 1.22173" />
                    <position ctrlrange="0 1.22173" forcerange="-2 2" />
                </default>
                <default class="thhub">
                    <joint range="-0.20943999999999999 0.20943999999999999" />
                    <position ctrlrange="-0.20943999999999999 0.20943999999999999" kp="0.5" />
                </default>
                <default class="thmiddle">
                    <joint axis="0 -1 0" range="-0.69813199999999997 0.69813199999999997" />
                    <position ctrlrange="-0.69813199999999997 0.69813199999999997" kp="1.5" />
                </default>
                <default class="thdistal">
                    <joint range="-0.261799 1.5708" />
                    <position ctrlrange="-0.261799 1.5708" />
                </default>
            </default>
            <default class="metacarpal">
                <joint axis="0.57357599999999997 0 0.81915199999999999"
                    range="0 0.78539800000000004" />
                <position ctrlrange="0 0.78539800000000004" />
            </default>
            <default class="knuckle">
                <joint axis="0 -1 0" range="-0.34906599999999999 0.34906599999999999" />
                <position ctrlrange="-0.34906599999999999 0.34906599999999999" />
            </default>
            <default class="proximal">
                <joint range="-0.261799 1.5708" />
                <position ctrlrange="-0.261799 1.5708" />
            </default>
            <default class="middle_distal">
                <joint range="0 1.5708" />
                <position ctrlrange="0 3.1415000000000002" kp="0.5" />
            </default>
            <default class="plastic">
                <geom solref="0.0050000000000000001 1" solimp="0.5 0.98999999999999999 0.0001" />
                <default class="plastic_visual">
                    <geom type="mesh" contype="0" conaffinity="0" group="2" material="black" />
                </default>
                <default class="plastic_collision">
                    <geom group="3" />
                </default>
            </default>
        </default>
    </default>
    <asset>
        <material name="black" specular="0.5" shininess="0.25"
            rgba="0.16355 0.16355 0.16355 1" />
        <material name="gray" specular="0" shininess="0.25"
            rgba="0.80847999999999998 0.80847999999999998 0.80847999999999998 1" />
        <material name="metallic" specular="0" shininess="0.25"
            rgba="0.90000000000000002 0.90000000000000002 0.90000000000000002 1" />
        <material name="tip_red" specular="0" shininess="0.25"
            rgba="0.3411764705882353 0.011764705882352941 0.082352941176470587 1" />
        <mesh name="forearm_0" class="right_hand"
            file="forearm_0.obj" />
        <mesh name="forearm_1" class="right_hand"
            file="forearm_1.obj" />
        <mesh name="forearm_collision" class="right_hand"
            file="forearm_collision.obj" />
        <mesh name="wrist" class="right_hand"
            file="wrist.obj" />
        <mesh name="palm" class="right_hand"
            file="palm.obj" />
        <mesh name="f_knuckle" class="right_hand"
            file="f_knuckle.obj" />
        <mesh name="f_proximal" class="right_hand"
            file="f_proximal.obj" />
        <mesh name="f_middle" class="right_hand"
            file="f_middle.obj" />
        <mesh name="f_distal_pst" class="right_hand"
            file="f_distal_pst.obj" />
        <mesh name="lf_metacarpal" class="right_hand"
            file="lf_metacarpal.obj" />
        <mesh name="th_proximal" class="right_hand"
            file="th_proximal.obj" />
        <mesh name="th_middle" class="right_hand"
            file="th_middle.obj" />
        <mesh name="th_distal_pst" class="right_hand"
            file="th_distal_pst.obj" />
        <mesh name="f_distal_mstXL" class="right_hand"
            file="f_distal_mstXL.stl" />
        <mesh name="th_distal_mst" class="right_hand"
            file="th_distal_mst.stl" />
    </asset>
    <worldbody>
        <body name="rh_forearm_base" childclass="right_hand" pos="0 0 0" quat="0 1 0 1">
            <inertial pos="0 0 0.089999999999999997" mass="3"
                diaginertia="0.0138 0.0138 0.0074400000000000004" />
            <geom class="plastic_visual" material="gray" mesh="forearm_0" />
            <geom class="plastic_visual" mesh="forearm_1" />
            <geom class="plastic_collision" type="mesh"
                mesh="forearm_collision" />
            <geom class="plastic_collision" type="box"
                size="0.035000000000000003 0.035000000000000003 0.035000000000000003"
                pos="0.01 0 0.18099999999999999" quat="0.38018800000000003 0.92490899999999998 0 0" />
            <body name="rh_wrist" pos="0.01 0 0.21301" quat="1 0 0 1">
                <inertial pos="0 0 0.029000000000000001" quat="0.5 0.5 0.5 0.5"
                    mass="0.10000000000000001"
                    diaginertia="6.3999999999999997e-05 4.3800000000000001e-05 3.4999999999999997e-05" />
                <joint name="rh_WRJ2" class="wrist_y" />
                <geom class="plastic_visual" material="metallic"
                    mesh="wrist" />
                <geom class="plastic_collision" type="cylinder"
                    size="0.0135 0.014999999999999999" quat="0.499998 0.5 0.5 -0.50000199999999995" />
                <geom class="plastic_collision" type="cylinder"
                    size="0.010999999999999999 0.0050000000000000001"
                    pos="-0.025999999999999999 0 0.034000000000000002" quat="1 0 1 0" />
                <geom class="plastic_collision" type="cylinder"
                    size="0.010999999999999999 0.0050000000000000001"
                    pos="0.031 0 0.034000000000000002" quat="1 0 1 0" />
                <geom class="plastic_collision" type="box"
                    size="0.0135 0.0089999999999999993 0.0050000000000000001"
                    pos="-0.021000000000000001 0 0.010999999999999999"
                    quat="0.92387900000000001 0 0.38268400000000002 0" />
                <geom class="plastic_collision" type="box"
                    size="0.0135 0.0089999999999999993 0.0050000000000000001"
                    pos="0.025999999999999999 0 0.01"
                    quat="0.92387900000000001 0 -0.38268400000000002 0" />
                <body name="rh_palm" pos="0 0 0.034000000000000002">
                    <inertial pos="0 0 0.035000000000000003" quat="1 0 0 1"
                        mass="0.29999999999999999"
                        diaginertia="0.0005287 0.00035809999999999998 0.00019100000000000001" />
                    <joint name="rh_WRJ1" class="wrist_x" />
                    <site name="grasp_site" group="4"
                        pos="0 -0.035000000000000003 0.089999999999999997" />
                    <geom class="plastic_visual" mesh="palm" />
                    <geom class="plastic_collision" type="box"
                        size="0.031 0.0035000000000000001 0.049000000000000002"
                        pos="0.010999999999999999 0.0085000000000000006 0.037999999999999999" />
                    <geom class="plastic_collision" type="box"
                        size="0.017999999999999999 0.0085000000000000006 0.049000000000000002"
                        pos="-0.002 -0.0035000000000000001 0.037999999999999999" />
                    <geom class="plastic_collision" type="box"
                        size="0.012999999999999999 0.0085000000000000006 0.0050000000000000001"
                        pos="0.029000000000000001 -0.0035000000000000001 0.082000000000000003" />
                    <geom class="plastic_collision" type="box"
                        size="0.012999999999999999 0.0070000000000000001 0.0089999999999999993"
                        pos="0.026499999999999999 -0.001 0.070000000000000007"
                        quat="0.98724100000000004 0.099054500000000004 0.0124467 0.124052" />
                    <geom class="plastic_collision" type="box"
                        size="0.010500000000000001 0.0135 0.012"
                        pos="0.0315 -0.0085000000000000006 0.001" />
                    <geom class="plastic_collision" type="box"
                        size="0.010999999999999999 0.0025000000000000001 0.014999999999999999"
                        pos="0.012500000000000001 -0.014999999999999999 0.0040000000000000001"
                        quat="0.97133800000000003 0 0 -0.237703" />
                    <geom class="plastic_collision" type="box"
                        size="0.0089999999999999993 0.012 0.002"
                        pos="0.010999999999999999 0 0.088999999999999996" />
                    <geom class="plastic_collision" type="box"
                        size="0.01 0.012 0.02" pos="-0.029999999999999999 0 0.0089999999999999993" />
                    <body name="rh_ffknuckle" pos="0.033000000000000002 0 0.095000000000000001">
                        <inertial pos="0 0 0" quat="0.5 0.5 -0.5 0.5" mass="0.0080000000000000002"
                            diaginertia="3.2000000000000001e-07 2.6e-07 2.6e-07" />
                        <joint name="rh_FFJ4" class="knuckle" />
                        <geom class="plastic_visual" material="metallic"
                            pos="0 0 0.00050000000000000001" mesh="f_knuckle" />
                        <geom class="plastic_collision" type="cylinder"
                            size="0.0089999999999999993 0.0089999999999999993" quat="1 0 1 0" />
                        <body name="rh_ffproximal">
                            <inertial pos="0 0 0.022499999999999999" quat="1 0 0 1"
                                mass="0.029999999999999999"
                                diaginertia="1.0000000000000001e-05 9.7999999999999993e-06 1.7999999999999999e-06" />
                            <joint name="rh_FFJ3" class="proximal" />
                            <geom class="plastic_visual" mesh="f_proximal" />
                            <geom class="plastic_collision" type="capsule"
                                size="0.0089999999999999993 0.02" pos="0 0 0.025000000000000001" />
                            <body name="rh_ffmiddle" pos="0 0 0.044999999999999998">
                                <inertial pos="0 0 0.012500000000000001" quat="1 0 0 1"
                                    mass="0.017000000000000001"
                                    diaginertia="2.7e-06 2.6000000000000001e-06 8.7000000000000003e-07" />
                                <joint name="rh_FFJ2" class="middle_distal" />
                                <geom class="plastic_visual"
                                    mesh="f_middle" />
                                <geom class="plastic_collision"
                                    type="capsule" size="0.0089999999999999993 0.012500000000000001"
                                    pos="0 0 0.012500000000000001" />
                                <body name="rh_ffdistal" pos="0 0 0.025000000000000001">
                                    <inertial pos="0 0 0.013076900000000001" quat="1 0 0 1"
                                        mass="0.012999999999999999"
                                        diaginertia="1.28092e-06 1.1209200000000001e-06 5.3000000000000001e-07" />
                                    <joint name="rh_FFJ1" class="middle_distal" />
                                    <geom class="plastic_visual"
                                        material="tip_red" mesh="f_distal_mstXL" />
                                    <geom class="plastic_collision"
                                        type="mesh" mesh="f_distal_mstXL" />
                                    <site name="rh_ffdistal_tip" pos="0 0 0.025999999999999999" />
                                    <site name="rh_ffdistal_0" rgba="0 0 0 0.10000000000000001"
                                        size="0.001"
                                        pos="-0.0089999999999999993 0.001 0.019999999999999997"
                                        quat="-0.51332375272133191 -0.45928967348750754 0.48330481981365164 0.54034079233824406" />
                                    <site name="rh_ffdistal_1" rgba="0 0 0 0.10000000000000001"
                                        size="0.001"
                                        pos="-0.0060000000000000001 -0.0070000000000000001 0.017999999999999999"
                                        quat="0.2529586446421252 0.66989048185859246 -0.65289326067710574 -0.24695962540160049" />
                                    <site name="rh_ffdistal_2" rgba="0 0 0 0.10000000000000001"
                                        size="0.001"
                                        pos="-0.0070000000000000001 -0.0060000000000000001 0.012999999999999999"
                                        quat="0.22492365137833648 0.70276145297320181 -0.64178215193285315 -0.2089290806136547" />
                                    <site name="rh_ffdistal_3" rgba="0 0 0 0.10000000000000001"
                                        size="0.001"
                                        pos="-0.0089999999999999993 0.001 0.013999999999999999"
                                        quat="-0.53132580260612172 -0.45127671746772302 0.46428469380271281 0.54633500606957153" />
                                    <site name="rh_ffdistal_4" rgba="0 0 0 0.10000000000000001"
                                        size="0.001"
                                        pos="-0.0089999999999999993 0.001 0.025999999999999999"
                                        quat="-0.43495911576458707 -0.41496099549954835 0.55294802532831389 0.57694576964636013" />
                                    <site name="rh_ffdistal_5" rgba="0 0 0 0.10000000000000001"
                                        size="0.001"
                                        pos="0.0060000000000000001 -0.0050000000000000001 0.024999999999999998"
                                        quat="0.14602760182536398 -0.54510303421111916 0.77514651653874744 -0.28405369122194096" />
                                    <site name="rh_ffdistal_6" rgba="0 0 0 0.10000000000000001"
                                        size="0.001"
                                        pos="0.0089999999999999993 0.001 0.025999999999999999"
                                        quat="-0.43617952481929767 0.4141704662274982 -0.55122687654915836 0.57823799391182118" />
                                    <site name="rh_ffdistal_7" rgba="0 0 0 0.10000000000000001"
                                        size="0.001"
                                        pos="0.0070000000000000001 -0.0060000000000000001 0.019"
                                        quat="-0.25793475076104228 0.67083030139790467 -0.64883586528649795 0.249936773993258" />
                                    <site name="rh_ffdistal_8" rgba="0 0 0 0.10000000000000001"
                                        size="0.001"
                                        pos="0 -0.0080000000000000002 0.014999999999999999"
                                        quat="-0.00099992500843644515 0.73694473121766024 -0.67594930570303713 0.0019998500168728912" />
                                    <site name="rh_ffdistal_9" rgba="0 0 0 0.10000000000000001"
                                        size="0.001"
                                        pos="-0.0060000000000000001 -0.0050000000000000001 0.024999999999999998"
                                        quat="-0.14590650388691498 -0.54565035015243535 0.77450370213944575 0.28481749046418325" />
                                    <site name="rh_ffdistal_10" rgba="0 0 0 0.10000000000000001"
                                        size="0.001"
                                        pos="0.0089999999999999993 0.001 0.014999999999999999"
                                        quat="-0.52788255919441562 0.45589857384972277 -0.46889568231473661 0.54187944523366161" />
                                    <site name="rh_ffdistal_11" rgba="0 0 0 0.10000000000000001"
                                        size="0.001"
                                        pos="0.0040000000000000001 0 0.032000000000000001"
                                        quat="0.1050133375408553 -0.21402718317850514 0.74909514112476794 -0.61807850095474848" />
                                    <site name="rh_ffdistal_12" rgba="0 0 0 0.10000000000000001"
                                        size="0.001"
                                        pos="0 -0.0050000000000000001 0.028999999999999998"
                                        quat="0.0090026922075152616 -0.43913131989991105 0.89826862248318939 -0.014004187878357071" />
                                    <site name="rh_ffdistal_13" rgba="0 0 0 0.10000000000000001"
                                        size="0.001"
                                        pos="-0.0040000000000000001 0 0.032000000000000001"
                                        quat="-0.23003807445224358 0.062010263547996082 0.74912399028143661 -0.61810230439776748" />
                                    <site name="rh_ffdistal_14" rgba="0 0 0 0.10000000000000001"
                                        size="0.001"
                                        pos="0.0070000000000000001 -0.0060000000000000001 0.011999999999999999"
                                        quat="-0.23090973193876932 0.69872685119134037 -0.64174912512852755 0.2159155935011868" />
                                    <site name="rh_ffdistal_15" rgba="0 0 0 0.10000000000000001"
                                        size="0.001"
                                        pos="0.0089999999999999993 0.001 0.020999999999999998"
                                        quat="-0.50592968066124255 0.46693510053122572 -0.49193162625559544 0.5329259284435619" />
                                    <site name="rh_ffdistal_16" rgba="0 0 0 0.10000000000000001"
                                        size="0.001"
                                        pos="0 -0.0080000000000000002 0.021999999999999999"
                                        quat="0.0039998800053997292 -0.63798086086125694 0.76997690103944805 -0.0099997000134993252" />
                                </body>
                            </body>
                        </body>
                    </body>
                    <body name="rh_mfknuckle" pos="0.010999999999999999 0 0.099000000000000005">
                        <inertial pos="0 0 0" quat="0.5 0.5 -0.5 0.5" mass="0.0080000000000000002"
                            diaginertia="3.2000000000000001e-07 2.6e-07 2.6e-07" />
                        <joint name="rh_MFJ4" class="knuckle" />
                        <geom class="plastic_visual" material="metallic"
                            pos="0 0 0.00050000000000000001" mesh="f_knuckle" />
                        <geom class="plastic_collision" type="cylinder"
                            size="0.0089999999999999993 0.0089999999999999993" quat="1 0 1 0" />
                        <body name="rh_mfproximal">
                            <inertial pos="0 0 0.022499999999999999" quat="1 0 0 1"
                                mass="0.029999999999999999"
                                diaginertia="1.0000000000000001e-05 9.7999999999999993e-06 1.7999999999999999e-06" />
                            <joint name="rh_MFJ3" class="proximal" />
                            <geom class="plastic_visual" mesh="f_proximal" />
                            <geom class="plastic_collision" type="capsule"
                                size="0.0089999999999999993 0.02" pos="0 0 0.025000000000000001" />
                            <body name="rh_mfmiddle" pos="0 0 0.044999999999999998">
                                <inertial pos="0 0 0.012500000000000001" quat="1 0 0 1"
                                    mass="0.017000000000000001"
                                    diaginertia="2.7e-06 2.6000000000000001e-06 8.7000000000000003e-07" />
                                <joint name="rh_MFJ2" class="middle_distal" />
                                <geom class="plastic_visual"
                                    mesh="f_middle" />
                                <geom class="plastic_collision"
                                    type="capsule" size="0.0089999999999999993 0.012500000000000001"
                                    pos="0 0 0.012500000000000001" />
                                <body name="rh_mfdistal" pos="0 0 0.025000000000000001">
                                    <inertial pos="0 0 0.013076900000000001" quat="1 0 0 1"
                                        mass="0.012999999999999999"
                                        diaginertia="1.28092e-06 1.1209200000000001e-06 5.3000000000000001e-07" />
                                    <joint name="rh_MFJ1" class="middle_distal" />
                                    <geom class="plastic_visual"
                                        material="tip_red" mesh="f_distal_mstXL" />
                                    <geom class="plastic_collision"
                                        type="mesh" mesh="f_distal_mstXL" />
                                    <site name="rh_mfdistal_tip" pos="0 0 0.025999999999999999" />
                                    <site name="rh_mfdistal_0" rgba="0 0 0 0.10000000000000001"
                                        size="0.001"
                                        pos="-0.0089999999999999993 0.001 0.019999999999999997"
                                        quat="-0.51332375272133191 -0.45928967348750754 0.48330481981365164 0.54034079233824406" />
                                    <site name="rh_mfdistal_1" rgba="0 0 0 0.10000000000000001"
                                        size="0.001"
                                        pos="-0.0060000000000000001 -0.0070000000000000001 0.017999999999999999"
                                        quat="0.2529586446421252 0.66989048185859246 -0.65289326067710574 -0.24695962540160049" />
                                    <site name="rh_mfdistal_2" rgba="0 0 0 0.10000000000000001"
                                        size="0.001"
                                        pos="-0.0070000000000000001 -0.0060000000000000001 0.012999999999999999"
                                        quat="0.22492365137833648 0.70276145297320181 -0.64178215193285315 -0.2089290806136547" />
                                    <site name="rh_mfdistal_3" rgba="0 0 0 0.10000000000000001"
                                        size="0.001"
                                        pos="-0.0089999999999999993 0.001 0.013999999999999999"
                                        quat="-0.53132580260612172 -0.45127671746772302 0.46428469380271281 0.54633500606957153" />
                                    <site name="rh_mfdistal_4" rgba="0 0 0 0.10000000000000001"
                                        size="0.001"
                                        pos="-0.0089999999999999993 0.001 0.025999999999999999"
                                        quat="-0.43495911576458707 -0.41496099549954835 0.55294802532831389 0.57694576964636013" />
                                    <site name="rh_mfdistal_5" rgba="0 0 0 0.10000000000000001"
                                        size="0.001"
                                        pos="0.0060000000000000001 -0.0050000000000000001 0.024999999999999998"
                                        quat="0.14602760182536398 -0.54510303421111916 0.77514651653874744 -0.28405369122194096" />
                                    <site name="rh_mfdistal_6" rgba="0 0 0 0.10000000000000001"
                                        size="0.001"
                                        pos="0.0089999999999999993 0.001 0.025999999999999999"
                                        quat="-0.43617952481929767 0.4141704662274982 -0.55122687654915836 0.57823799391182118" />
                                    <site name="rh_mfdistal_7" rgba="0 0 0 0.10000000000000001"
                                        size="0.001"
                                        pos="0.0070000000000000001 -0.0060000000000000001 0.019"
                                        quat="-0.25793475076104228 0.67083030139790467 -0.64883586528649795 0.249936773993258" />
                                    <site name="rh_mfdistal_8" rgba="0 0 0 0.10000000000000001"
                                        size="0.001"
                                        pos="0 -0.0080000000000000002 0.014999999999999999"
                                        quat="-0.00099992500843644515 0.73694473121766024 -0.67594930570303713 0.0019998500168728912" />
                                    <site name="rh_mfdistal_9" rgba="0 0 0 0.10000000000000001"
                                        size="0.001"
                                        pos="-0.0060000000000000001 -0.0050000000000000001 0.024999999999999998"
                                        quat="-0.14590650388691498 -0.54565035015243535 0.77450370213944575 0.28481749046418325" />
                                    <site name="rh_mfdistal_10" rgba="0 0 0 0.10000000000000001"
                                        size="0.001"
                                        pos="0.0089999999999999993 0.001 0.014999999999999999"
                                        quat="-0.52788255919441562 0.45589857384972277 -0.46889568231473661 0.54187944523366161" />
                                    <site name="rh_mfdistal_11" rgba="0 0 0 0.10000000000000001"
                                        size="0.001"
                                        pos="0.0040000000000000001 0 0.032000000000000001"
                                        quat="0.1050133375408553 -0.21402718317850514 0.74909514112476794 -0.61807850095474848" />
                                    <site name="rh_mfdistal_12" rgba="0 0 0 0.10000000000000001"
                                        size="0.001"
                                        pos="0 -0.0050000000000000001 0.028999999999999998"
                                        quat="0.0090026922075152616 -0.43913131989991105 0.89826862248318939 -0.014004187878357071" />
                                    <site name="rh_mfdistal_13" rgba="0 0 0 0.10000000000000001"
                                        size="0.001"
                                        pos="-0.0040000000000000001 0 0.032000000000000001"
                                        quat="-0.23003807445224358 0.062010263547996082 0.74912399028143661 -0.61810230439776748" />
                                    <site name="rh_mfdistal_14" rgba="0 0 0 0.10000000000000001"
                                        size="0.001"
                                        pos="0.0070000000000000001 -0.0060000000000000001 0.011999999999999999"
                                        quat="-0.23090973193876932 0.69872685119134037 -0.64174912512852755 0.2159155935011868" />
                                    <site name="rh_mfdistal_15" rgba="0 0 0 0.10000000000000001"
                                        size="0.001"
                                        pos="0.0089999999999999993 0.001 0.020999999999999998"
                                        quat="-0.50592968066124255 0.46693510053122572 -0.49193162625559544 0.5329259284435619" />
                                    <site name="rh_mfdistal_16" rgba="0 0 0 0.10000000000000001"
                                        size="0.001"
                                        pos="0 -0.0080000000000000002 0.021999999999999999"
                                        quat="0.0039998800053997292 -0.63798086086125694 0.76997690103944805 -0.0099997000134993252" />
                                </body>
                            </body>
                        </body>
                    </body>
                    <body name="rh_rfknuckle" pos="-0.010999999999999999 0 0.095000000000000001">
                        <inertial pos="0 0 0" quat="0.5 0.5 -0.5 0.5" mass="0.0080000000000000002"
                            diaginertia="3.2000000000000001e-07 2.6e-07 2.6e-07" />
                        <joint name="rh_RFJ4" class="knuckle" axis="0 1 0" />
                        <geom class="plastic_visual" material="metallic"
                            pos="0 0 0.00050000000000000001" mesh="f_knuckle" />
                        <geom class="plastic_collision" type="cylinder"
                            size="0.0089999999999999993 0.0089999999999999993" quat="1 0 1 0" />
                        <body name="rh_rfproximal">
                            <inertial pos="0 0 0.022499999999999999" quat="1 0 0 1"
                                mass="0.029999999999999999"
                                diaginertia="1.0000000000000001e-05 9.7999999999999993e-06 1.7999999999999999e-06" />
                            <joint name="rh_RFJ3" class="proximal" />
                            <geom class="plastic_visual" mesh="f_proximal" />
                            <geom class="plastic_collision" type="capsule"
                                size="0.0089999999999999993 0.02" pos="0 0 0.025000000000000001" />
                            <body name="rh_rfmiddle" pos="0 0 0.044999999999999998">
                                <inertial pos="0 0 0.012500000000000001" quat="1 0 0 1"
                                    mass="0.017000000000000001"
                                    diaginertia="2.7e-06 2.6000000000000001e-06 8.7000000000000003e-07" />
                                <joint name="rh_RFJ2" class="middle_distal" />
                                <geom class="plastic_visual"
                                    mesh="f_middle" />
                                <geom class="plastic_collision"
                                    type="capsule" size="0.0089999999999999993 0.012500000000000001"
                                    pos="0 0 0.012500000000000001" />
                                <body name="rh_rfdistal" pos="0 0 0.025000000000000001">
                                    <inertial pos="0 0 0.013076900000000001" quat="1 0 0 1"
                                        mass="0.012999999999999999"
                                        diaginertia="1.28092e-06 1.1209200000000001e-06 5.3000000000000001e-07" />
                                    <joint name="rh_RFJ1" class="middle_distal" />
                                    <geom class="plastic_visual"
                                        material="tip_red" mesh="f_distal_mstXL" />
                                    <geom class="plastic_collision"
                                        type="mesh" mesh="f_distal_mstXL" />
                                    <site name="rh_rfdistal_tip" pos="0 0 0.025999999999999999" />
                                    <site name="rh_rfdistal_0" rgba="0 0 0 0.10000000000000001"
                                        size="0.001"
                                        pos="-0.0089999999999999993 0.001 0.019999999999999997"
                                        quat="-0.51332375272133191 -0.45928967348750754 0.48330481981365164 0.54034079233824406" />
                                    <site name="rh_rfdistal_1" rgba="0 0 0 0.10000000000000001"
                                        size="0.001"
                                        pos="-0.0060000000000000001 -0.0070000000000000001 0.017999999999999999"
                                        quat="0.2529586446421252 0.66989048185859246 -0.65289326067710574 -0.24695962540160049" />
                                    <site name="rh_rfdistal_2" rgba="0 0 0 0.10000000000000001"
                                        size="0.001"
                                        pos="-0.0070000000000000001 -0.0060000000000000001 0.012999999999999999"
                                        quat="0.22492365137833648 0.70276145297320181 -0.64178215193285315 -0.2089290806136547" />
                                    <site name="rh_rfdistal_3" rgba="0 0 0 0.10000000000000001"
                                        size="0.001"
                                        pos="-0.0089999999999999993 0.001 0.013999999999999999"
                                        quat="-0.53132580260612172 -0.45127671746772302 0.46428469380271281 0.54633500606957153" />
                                    <site name="rh_rfdistal_4" rgba="0 0 0 0.10000000000000001"
                                        size="0.001"
                                        pos="-0.0089999999999999993 0.001 0.025999999999999999"
                                        quat="-0.43495911576458707 -0.41496099549954835 0.55294802532831389 0.57694576964636013" />
                                    <site name="rh_rfdistal_5" rgba="0 0 0 0.10000000000000001"
                                        size="0.001"
                                        pos="0.0060000000000000001 -0.0050000000000000001 0.024999999999999998"
                                        quat="0.14602760182536398 -0.54510303421111916 0.77514651653874744 -0.28405369122194096" />
                                    <site name="rh_rfdistal_6" rgba="0 0 0 0.10000000000000001"
                                        size="0.001"
                                        pos="0.0089999999999999993 0.001 0.025999999999999999"
                                        quat="-0.43617952481929767 0.4141704662274982 -0.55122687654915836 0.57823799391182118" />
                                    <site name="rh_rfdistal_7" rgba="0 0 0 0.10000000000000001"
                                        size="0.001"
                                        pos="0.0070000000000000001 -0.0060000000000000001 0.019"
                                        quat="-0.25793475076104228 0.67083030139790467 -0.64883586528649795 0.249936773993258" />
                                    <site name="rh_rfdistal_8" rgba="0 0 0 0.10000000000000001"
                                        size="0.001"
                                        pos="0 -0.0080000000000000002 0.014999999999999999"
                                        quat="-0.00099992500843644515 0.73694473121766024 -0.67594930570303713 0.0019998500168728912" />
                                    <site name="rh_rfdistal_9" rgba="0 0 0 0.10000000000000001"
                                        size="0.001"
                                        pos="-0.0060000000000000001 -0.0050000000000000001 0.024999999999999998"
                                        quat="-0.14590650388691498 -0.54565035015243535 0.77450370213944575 0.28481749046418325" />
                                    <site name="rh_rfdistal_10" rgba="0 0 0 0.10000000000000001"
                                        size="0.001"
                                        pos="0.0089999999999999993 0.001 0.014999999999999999"
                                        quat="-0.52788255919441562 0.45589857384972277 -0.46889568231473661 0.54187944523366161" />
                                    <site name="rh_rfdistal_11" rgba="0 0 0 0.10000000000000001"
                                        size="0.001"
                                        pos="0.0040000000000000001 0 0.032000000000000001"
                                        quat="0.1050133375408553 -0.21402718317850514 0.74909514112476794 -0.61807850095474848" />
                                    <site name="rh_rfdistal_12" rgba="0 0 0 0.10000000000000001"
                                        size="0.001"
                                        pos="0 -0.0050000000000000001 0.028999999999999998"
                                        quat="0.0090026922075152616 -0.43913131989991105 0.89826862248318939 -0.014004187878357071" />
                                    <site name="rh_rfdistal_13" rgba="0 0 0 0.10000000000000001"
                                        size="0.001"
                                        pos="-0.0040000000000000001 0 0.032000000000000001"
                                        quat="-0.23003807445224358 0.062010263547996082 0.74912399028143661 -0.61810230439776748" />
                                    <site name="rh_rfdistal_14" rgba="0 0 0 0.10000000000000001"
                                        size="0.001"
                                        pos="0.0070000000000000001 -0.0060000000000000001 0.011999999999999999"
                                        quat="-0.23090973193876932 0.69872685119134037 -0.64174912512852755 0.2159155935011868" />
                                    <site name="rh_rfdistal_15" rgba="0 0 0 0.10000000000000001"
                                        size="0.001"
                                        pos="0.0089999999999999993 0.001 0.020999999999999998"
                                        quat="-0.50592968066124255 0.46693510053122572 -0.49193162625559544 0.5329259284435619" />
                                    <site name="rh_rfdistal_16" rgba="0 0 0 0.10000000000000001"
                                        size="0.001"
                                        pos="0 -0.0080000000000000002 0.021999999999999999"
                                        quat="0.0039998800053997292 -0.63798086086125694 0.76997690103944805 -0.0099997000134993252" />
                                </body>
                            </body>
                        </body>
                    </body>
                    <body name="rh_lfmetacarpal" pos="-0.033000000000000002 0 0.020709999999999999">
                        <inertial pos="0 0 0.040000000000000001" quat="1 0 0 1"
                            mass="0.029999999999999999"
                            diaginertia="1.6379999999999999e-05 1.45e-05 4.2719999999999999e-06" />
                        <joint name="rh_LFJ5" class="metacarpal" />
                        <geom class="plastic_visual" mesh="lf_metacarpal" />
                        <geom class="plastic_collision" type="box"
                            size="0.010999999999999999 0.012 0.025000000000000001"
                            pos="0.002 0 0.033000000000000002" />
                        <body name="rh_lfknuckle" pos="0 0 0.065790000000000001">
                            <inertial pos="0 0 0" quat="0.5 0.5 -0.5 0.5"
                                mass="0.0080000000000000002"
                                diaginertia="3.2000000000000001e-07 2.6e-07 2.6e-07" />
                            <joint name="rh_LFJ4" class="knuckle" axis="0 1 0" />
                            <geom class="plastic_visual"
                                material="metallic" pos="0 0 0.00050000000000000001"
                                mesh="f_knuckle" />
                            <geom class="plastic_collision" type="cylinder"
                                size="0.0089999999999999993 0.0089999999999999993" quat="1 0 1 0" />
                            <body name="rh_lfproximal">
                                <inertial pos="0 0 0.022499999999999999" quat="1 0 0 1"
                                    mass="0.029999999999999999"
                                    diaginertia="1.0000000000000001e-05 9.7999999999999993e-06 1.7999999999999999e-06" />
                                <joint name="rh_LFJ3" class="proximal" />
                                <geom class="plastic_visual"
                                    mesh="f_proximal" />
                                <geom class="plastic_collision"
                                    type="capsule" size="0.0089999999999999993 0.02"
                                    pos="0 0 0.025000000000000001" />
                                <body name="rh_lfmiddle" pos="0 0 0.044999999999999998">
                                    <inertial pos="0 0 0.012500000000000001" quat="1 0 0 1"
                                        mass="0.017000000000000001"
                                        diaginertia="2.7e-06 2.6000000000000001e-06 8.7000000000000003e-07" />
                                    <joint name="rh_LFJ2" class="middle_distal" />
                                    <geom class="plastic_visual"
                                        mesh="f_middle" />
                                    <geom class="plastic_collision"
                                        type="capsule"
                                        size="0.0089999999999999993 0.012500000000000001"
                                        pos="0 0 0.012500000000000001" />
                                    <body name="rh_lfdistal" pos="0 0 0.025000000000000001">
                                        <inertial pos="0 0 0.013076900000000001" quat="1 0 0 1"
                                            mass="0.012999999999999999"
                                            diaginertia="1.28092e-06 1.1209200000000001e-06 5.3000000000000001e-07" />
                                        <joint name="rh_LFJ1" class="middle_distal" />
                                        <geom class="plastic_visual"
                                            material="tip_red" mesh="f_distal_mstXL" />
                                        <geom class="plastic_collision"
                                            type="mesh" mesh="f_distal_mstXL" />
                                        <site name="rh_lfdistal_tip" pos="0 0 0.025999999999999999" />
                                        <site name="rh_lfdistal_0" rgba="0 0 0 0.10000000000000001"
                                            size="0.001"
                                            pos="-0.0089999999999999993 0.001 0.019999999999999997"
                                            quat="-0.51332375272133191 -0.45928967348750754 0.48330481981365164 0.54034079233824406" />
                                        <site name="rh_lfdistal_1" rgba="0 0 0 0.10000000000000001"
                                            size="0.001"
                                            pos="-0.0060000000000000001 -0.0070000000000000001 0.017999999999999999"
                                            quat="0.2529586446421252 0.66989048185859246 -0.65289326067710574 -0.24695962540160049" />
                                        <site name="rh_lfdistal_2" rgba="0 0 0 0.10000000000000001"
                                            size="0.001"
                                            pos="-0.0070000000000000001 -0.0060000000000000001 0.012999999999999999"
                                            quat="0.22492365137833648 0.70276145297320181 -0.64178215193285315 -0.2089290806136547" />
                                        <site name="rh_lfdistal_3" rgba="0 0 0 0.10000000000000001"
                                            size="0.001"
                                            pos="-0.0089999999999999993 0.001 0.013999999999999999"
                                            quat="-0.53132580260612172 -0.45127671746772302 0.46428469380271281 0.54633500606957153" />
                                        <site name="rh_lfdistal_4" rgba="0 0 0 0.10000000000000001"
                                            size="0.001"
                                            pos="-0.0089999999999999993 0.001 0.025999999999999999"
                                            quat="-0.43495911576458707 -0.41496099549954835 0.55294802532831389 0.57694576964636013" />
                                        <site name="rh_lfdistal_5" rgba="0 0 0 0.10000000000000001"
                                            size="0.001"
                                            pos="0.0060000000000000001 -0.0050000000000000001 0.024999999999999998"
                                            quat="0.14602760182536398 -0.54510303421111916 0.77514651653874744 -0.28405369122194096" />
                                        <site name="rh_lfdistal_6" rgba="0 0 0 0.10000000000000001"
                                            size="0.001"
                                            pos="0.0089999999999999993 0.001 0.025999999999999999"
                                            quat="-0.43617952481929767 0.4141704662274982 -0.55122687654915836 0.57823799391182118" />
                                        <site name="rh_lfdistal_7" rgba="0 0 0 0.10000000000000001"
                                            size="0.001"
                                            pos="0.0070000000000000001 -0.0060000000000000001 0.019"
                                            quat="-0.25793475076104228 0.67083030139790467 -0.64883586528649795 0.249936773993258" />
                                        <site name="rh_lfdistal_8" rgba="0 0 0 0.10000000000000001"
                                            size="0.001"
                                            pos="0 -0.0080000000000000002 0.014999999999999999"
                                            quat="-0.00099992500843644515 0.73694473121766024 -0.67594930570303713 0.0019998500168728912" />
                                        <site name="rh_lfdistal_9" rgba="0 0 0 0.10000000000000001"
                                            size="0.001"
                                            pos="-0.0060000000000000001 -0.0050000000000000001 0.024999999999999998"
                                            quat="-0.14590650388691498 -0.54565035015243535 0.77450370213944575 0.28481749046418325" />
                                        <site name="rh_lfdistal_10" rgba="0 0 0 0.10000000000000001"
                                            size="0.001"
                                            pos="0.0089999999999999993 0.001 0.014999999999999999"
                                            quat="-0.52788255919441562 0.45589857384972277 -0.46889568231473661 0.54187944523366161" />
                                        <site name="rh_lfdistal_11" rgba="0 0 0 0.10000000000000001"
                                            size="0.001"
                                            pos="0.0040000000000000001 0 0.032000000000000001"
                                            quat="0.1050133375408553 -0.21402718317850514 0.74909514112476794 -0.61807850095474848" />
                                        <site name="rh_lfdistal_12" rgba="0 0 0 0.10000000000000001"
                                            size="0.001"
                                            pos="0 -0.0050000000000000001 0.028999999999999998"
                                            quat="0.0090026922075152616 -0.43913131989991105 0.89826862248318939 -0.014004187878357071" />
                                        <site name="rh_lfdistal_13" rgba="0 0 0 0.10000000000000001"
                                            size="0.001"
                                            pos="-0.0040000000000000001 0 0.032000000000000001"
                                            quat="-0.23003807445224358 0.062010263547996082 0.74912399028143661 -0.61810230439776748" />
                                        <site name="rh_lfdistal_14" rgba="0 0 0 0.10000000000000001"
                                            size="0.001"
                                            pos="0.0070000000000000001 -0.0060000000000000001 0.011999999999999999"
                                            quat="-0.23090973193876932 0.69872685119134037 -0.64174912512852755 0.2159155935011868" />
                                        <site name="rh_lfdistal_15" rgba="0 0 0 0.10000000000000001"
                                            size="0.001"
                                            pos="0.0089999999999999993 0.001 0.020999999999999998"
                                            quat="-0.50592968066124255 0.46693510053122572 -0.49193162625559544 0.5329259284435619" />
                                        <site name="rh_lfdistal_16" rgba="0 0 0 0.10000000000000001"
                                            size="0.001"
                                            pos="0 -0.0080000000000000002 0.021999999999999999"
                                            quat="0.0039998800053997292 -0.63798086086125694 0.76997690103944805 -0.0099997000134993252" />
                                    </body>
                                </body>
                            </body>
                        </body>
                    </body>
                    <body name="rh_thbase"
                        pos="0.034000000000000002 -0.0085800000000000008 0.029000000000000001"
                        quat="0.92388000000000003 0 0.382683 0">
                        <inertial pos="0 0 0" mass="0.01" diaginertia="1.6e-07 1.6e-07 1.6e-07" />
                        <joint name="rh_THJ5" class="thbase" />
                        <geom class="plastic_collision"
                            size="0.012999999999999999" />
                        <body name="rh_thproximal">
                            <inertial pos="0 0 0.019" mass="0.040000000000000001"
                                diaginertia="1.36e-05 1.36e-05 3.1300000000000001e-06" />
                            <joint name="rh_THJ4" class="thproximal" />
                            <geom class="plastic_visual" mesh="th_proximal" />
                            <geom class="plastic_collision" type="capsule"
                                size="0.010500000000000001 0.0089999999999999993" pos="0 0 0.02" />
                            <body name="rh_thhub" pos="0 0 0.037999999999999999">
                                <inertial pos="0 0 0" mass="0.0050000000000000001"
                                    diaginertia="9.9999999999999995e-07 9.9999999999999995e-07 2.9999999999999999e-07" />
                                <joint name="rh_THJ3" class="thhub" />
                                <geom class="plastic_collision"
                                    size="0.010999999999999999" />
                                <body name="rh_thmiddle">
                                    <inertial pos="0 0 0.016" mass="0.02"
                                        diaginertia="5.1000000000000003e-06 5.1000000000000003e-06 1.2100000000000001e-06" />
                                    <joint name="rh_THJ2" class="thmiddle" />
                                    <geom class="plastic_visual"
                                        mesh="th_middle" />
                                    <geom class="plastic_collision"
                                        type="capsule"
                                        size="0.0089999999999999993 0.0089999999999999993"
                                        pos="0 0 0.012" />
                                    <geom class="plastic_collision"
                                        size="0.01" pos="0 0 0.029999999999999999" />
                                    <body name="rh_thdistal" pos="0 0 0.032000000000000001"
                                        quat="1 0 0 -1">
                                        <inertial pos="0 0 0.0145588" quat="1 0 0 1"
                                            mass="0.017000000000000001"
                                            diaginertia="2.37794e-06 2.2779400000000001e-06 9.9999999999999995e-07" />
                                        <joint name="rh_THJ1" class="thdistal" />
                                        <geom class="plastic_visual"
                                            material="tip_red" mesh="th_distal_mst" />
                                        <geom class="plastic_collision"
                                            type="mesh" mesh="th_distal_mst" />
                                        <site name="rh_thdistal_tip" pos="0 0 0.025999999999999999" />
                                        <site name="rh_thdistal_0" rgba="0 0 0 0.10000000000000001"
                                            size="0.001"
                                            pos="-0.0089999999999999993 0.001 0.019999999999999997"
                                            quat="-0.51332375272133191 -0.45928967348750754 0.48330481981365164 0.54034079233824406" />
                                        <site name="rh_thdistal_1" rgba="0 0 0 0.10000000000000001"
                                            size="0.001"
                                            pos="-0.0060000000000000001 -0.0070000000000000001 0.017999999999999999"
                                            quat="0.2529586446421252 0.66989048185859246 -0.65289326067710574 -0.24695962540160049" />
                                        <site name="rh_thdistal_2" rgba="0 0 0 0.10000000000000001"
                                            size="0.001"
                                            pos="-0.0070000000000000001 -0.0060000000000000001 0.012999999999999999"
                                            quat="0.22492365137833648 0.70276145297320181 -0.64178215193285315 -0.2089290806136547" />
                                        <site name="rh_thdistal_3" rgba="0 0 0 0.10000000000000001"
                                            size="0.001"
                                            pos="-0.0089999999999999993 0.001 0.013999999999999999"
                                            quat="-0.53132580260612172 -0.45127671746772302 0.46428469380271281 0.54633500606957153" />
                                        <site name="rh_thdistal_4" rgba="0 0 0 0.10000000000000001"
                                            size="0.001"
                                            pos="-0.0089999999999999993 0.001 0.025999999999999999"
                                            quat="-0.43495911576458707 -0.41496099549954835 0.55294802532831389 0.57694576964636013" />
                                        <site name="rh_thdistal_5" rgba="0 0 0 0.10000000000000001"
                                            size="0.001"
                                            pos="0.0060000000000000001 -0.0050000000000000001 0.024999999999999998"
                                            quat="0.14602760182536398 -0.54510303421111916 0.77514651653874744 -0.28405369122194096" />
                                        <site name="rh_thdistal_6" rgba="0 0 0 0.10000000000000001"
                                            size="0.001"
                                            pos="0.0089999999999999993 0.001 0.025999999999999999"
                                            quat="-0.43617952481929767 0.4141704662274982 -0.55122687654915836 0.57823799391182118" />
                                        <site name="rh_thdistal_7" rgba="0 0 0 0.10000000000000001"
                                            size="0.001"
                                            pos="0.0070000000000000001 -0.0060000000000000001 0.019"
                                            quat="-0.25793475076104228 0.67083030139790467 -0.64883586528649795 0.249936773993258" />
                                        <site name="rh_thdistal_8" rgba="0 0 0 0.10000000000000001"
                                            size="0.001"
                                            pos="0 -0.0080000000000000002 0.014999999999999999"
                                            quat="-0.00099992500843644515 0.73694473121766024 -0.67594930570303713 0.0019998500168728912" />
                                        <site name="rh_thdistal_9" rgba="0 0 0 0.10000000000000001"
                                            size="0.001"
                                            pos="-0.0060000000000000001 -0.0050000000000000001 0.024999999999999998"
                                            quat="-0.14590650388691498 -0.54565035015243535 0.77450370213944575 0.28481749046418325" />
                                        <site name="rh_thdistal_10" rgba="0 0 0 0.10000000000000001"
                                            size="0.001"
                                            pos="0.0089999999999999993 0.001 0.014999999999999999"
                                            quat="-0.52788255919441562 0.45589857384972277 -0.46889568231473661 0.54187944523366161" />
                                        <site name="rh_thdistal_11" rgba="0 0 0 0.10000000000000001"
                                            size="0.001"
                                            pos="0.0040000000000000001 0 0.032000000000000001"
                                            quat="0.1050133375408553 -0.21402718317850514 0.74909514112476794 -0.61807850095474848" />
                                        <site name="rh_thdistal_12" rgba="0 0 0 0.10000000000000001"
                                            size="0.001"
                                            pos="0 -0.0050000000000000001 0.028999999999999998"
                                            quat="0.0090026922075152616 -0.43913131989991105 0.89826862248318939 -0.014004187878357071" />
                                        <site name="rh_thdistal_13" rgba="0 0 0 0.10000000000000001"
                                            size="0.001"
                                            pos="-0.0040000000000000001 0 0.032000000000000001"
                                            quat="-0.23003807445224358 0.062010263547996082 0.74912399028143661 -0.61810230439776748" />
                                        <site name="rh_thdistal_14" rgba="0 0 0 0.10000000000000001"
                                            size="0.001"
                                            pos="0.0070000000000000001 -0.0060000000000000001 0.011999999999999999"
                                            quat="-0.23090973193876932 0.69872685119134037 -0.64174912512852755 0.2159155935011868" />
                                        <site name="rh_thdistal_15" rgba="0 0 0 0.10000000000000001"
                                            size="0.001"
                                            pos="0.0089999999999999993 0.001 0.020999999999999998"
                                            quat="-0.50592968066124255 0.46693510053122572 -0.49193162625559544 0.5329259284435619" />
                                        <site name="rh_thdistal_16" rgba="0 0 0 0.10000000000000001"
                                            size="0.001"
                                            pos="0 -0.0080000000000000002 0.021999999999999999"
                                            quat="0.0039998800053997292 -0.63798086086125694 0.76997690103944805 -0.0099997000134993252" />
                                    </body>
                                </body>
                            </body>
                        </body>
                    </body>
                </body>
            </body>
        </body>
    </worldbody>
    <contact>
        <exclude body1="rh_wrist" body2="rh_forearm_base" />
        <exclude body1="rh_thproximal" body2="rh_thmiddle" />
    </contact>
    <actuator>
        <position name="rh_A_WRJ2" class="wrist_y" joint="rh_WRJ2" kp="100" kv="10" />
        <position name="rh_A_WRJ1" class="wrist_x" joint="rh_WRJ1" kp="100" kv="10" />
        <position name="rh_A_THJ5" class="thbase" joint="rh_THJ5" kp="100" kv="10" />
        <position name="rh_A_THJ4" class="thproximal" joint="rh_THJ4" kp="100" kv="10" />
        <position name="rh_A_THJ3" class="thhub" joint="rh_THJ3" kp="100" kv="10" />
        <position name="rh_A_THJ2" class="thdistal" joint="rh_THJ2" kp="100" kv="10" />
        <position name="rh_A_THJ1" class="thdistal" joint="rh_THJ1" kp="100" kv="10" />
        <position name="rh_A_FFJ4" class="knuckle" joint="rh_FFJ4" kp="100" kv="10" />
        <position name="rh_A_FFJ3" class="proximal" joint="rh_FFJ3" kp="100" kv="10" />
        <position name="rh_A_FFJ2" class="thdistal" joint="rh_FFJ2" kp="100" kv="10" />
        <position name="rh_A_FFJ1" class="thdistal" joint="rh_FFJ1" kp="100" kv="10" />
        <position name="rh_A_MFJ4" class="knuckle" joint="rh_MFJ4" kp="100" kv="10" />
        <position name="rh_A_MFJ3" class="proximal" joint="rh_MFJ3" kp="100" kv="10" />
        <position name="rh_A_MFJ2" class="thdistal" joint="rh_MFJ2" kp="100" kv="10" />
        <position name="rh_A_MFJ1" class="thdistal" joint="rh_MFJ1" kp="100" kv="10" />
        <position name="rh_A_RFJ4" class="knuckle" joint="rh_RFJ4" kp="100" kv="10" />
        <position name="rh_A_RFJ3" class="proximal" joint="rh_RFJ3" kp="100" kv="10" />
        <position name="rh_A_RFJ2" class="thdistal" joint="rh_RFJ2" kp="100" kv="10" />
        <position name="rh_A_RFJ1" class="thdistal" joint="rh_RFJ1" kp="100" kv="10" />
        <position name="rh_A_LFJ5" class="metacarpal" joint="rh_LFJ5" kp="100" kv="10" />
        <position name="rh_A_LFJ4" class="knuckle" joint="rh_LFJ4" kp="100" kv="10" />
        <position name="rh_A_LFJ3" class="proximal" joint="rh_LFJ3" kp="100" kv="10" />
        <position name="rh_A_LFJ2" class="thdistal" joint="rh_LFJ2" kp="100" kv="10" />
        <position name="rh_A_LFJ1" class="thdistal" joint="rh_LFJ1" kp="100" kv="10" />
    </actuator>
</mujoco>